Workbook
Name asdasd: #REF!
Name asdasd: #REF!
Name asdasdasdefasdf: #REF!
Name asdasdasdefasdf: #REF!
Name DFGDFG: #REF!
Name DFGDFG: #REF!
Name FDFSDFSD: #REF!
Name FDFSDFSD: #REF!
Name GHFHGF: #REF!
Name GHFHGF: #REF!
Name ghjghj: #REF!
Name ghjghj: #REF!
Name GRTG: #REF!
Name GRTG: #REF!
Name gyhfgh: #REF!
Name gyhfgh: #REF!
Name HGVG: #REF!
Name HGVG: #REF!
Name IND: #REF!
Name IND: #REF!
Name INDT: #REF!
Name INDT: #REF!
Name ORÇ: #REF!
Name ORÇ: #REF!
Name ORÇDET: #REF!
Name ORÇDET: #REF!
Name PF04.011: #REF!
Name PF04.011: #REF!
Name RES: #REF!
Name RES: #REF!
Name sadfsd: #REF!
Name sadfsd: #REF!
Name saswd: #REF!
Name saswd: #REF!
Name SDFSDF: #REF!
Name SDFSDF: #REF!
Name sdfsfd: #REF!
Name sdfsfd: #REF!

Sheet ORÇ#1
A1: Column1 | B1: Column2 | C1: Column3 | D1: Column4 | E1: Column5 | F1: Column6 | G1: Column7 | H1: Column8 | I1: Column9 | J1: Column10 | K1: Column11 | L1: Column12 | M1: Column13 | N1: Column14 | O1: Column15 | P1: Column16 | Q1: Column17 | R1: Column18 | S1: Column19 | T1: Column20 | U1: Column21 | V1: Column22 | W1: Column23 | X1: Column24 | Y1: Column25 | Z1: Column26 | AA1: Column27 | AB1: Column28 | AC1: Column29 | AD1: Column30 | AE1: Column31 | AF1: Column32 | AG1: Column33 | AH1: Column34 | AI1: Column35 | AJ1: Column36 | AK1: Column37
K6: a | W6: a | AA6: AAS | AC6: AAS
M7: ITEM | N7: CPU | O7: SINAPI | P7: DESCRIÇÃO DO SERVIÇO | Q7: QUANT. | R7: UNID. | S7: PREÇO UNITÁRIO | V7: PREÇO TOTAL | X7: PREÇO UNIT. M.O. | Y7: TOTAL MÃO DE OBRA | Z7: PREÇO UNIT. MAT. | AA7: TOTAL MATERIAL | AB7: PREÇO UNIT. EQUIP. | AC7: TOTAL EQUIPAMENTO | AE7: PREÇO TOTAL + BDI | AG7: INCIDÊNCIA (%) | AI7: OBSERVAÇÕES
AF8: 0 | AH8: 0
A9: n1 | F9: 1 | L9: 1 | M9: 1 | N9: CI | P9: CUSTOS INDIRETOS | V9: 224917,9 | Y9: 221273,5002 | AA9: 3644,3998 | AC9: 0 | AE9: 269901,48 | AF9: 0 | AG9: 0,036284423385 | AH9: 0 | AK9: 0
L10: 0
A11: n2 | B11: 1 | C11: 1 | G11: 1 | H11: CI | I11: CI.1 | M11: 1.1 | N11: CI.1 | P11: CUSTO ADMINISTRATIVO | V11: 224917,9 | Y11: 221273,5002 | AA11: 3644,3998 | AC11: 0 | AE11: 269901,48 | AF11: 0 | AG11: 0,036284423385 | AH11: 0 | AK11: 0
L12: 0
A13: n3 | B13: 1 | C13: 1 | D13: 1 | G13: 11 | M13: 1.1.1 | O13: 93567 | P13: ENGENHEIRO CIVIL DE OBRA PLENO COM ENCARGOS COMPLEMENTARES | Q13: 10 | R13: MES | S13: 22491,79 | V13: 224917,9 | X13: 22127,35 | Y13: 221273,5002 | Z13: 364,44 | AA13: 3644,3998 | AB13: 0 | AC13: 0 | AE13: 269901,48 | AF13: 0 | AG13: 0,036284423385 | AH13: 0 | AK13: 0
A14: n4 | B14: 1 | C14: 1 | D14: 1 | E14: 1 | G14: 111 | H14: 93567 | I14: 2 | J14: 93567-2 | L14: 0 | M14: 1.1.1.1 | O14: 40813 | P14: ENGENHEIRO CIVIL DE OBRA PLENO (MENSALISTA) | Q14: 1 | R14: MES | S14: 21872,32 | T14: 10 | U14: 10 | V14: 21872,32 | AE14: 26246,784 | AF14: 0 | AG14: 10 MES | AH14: 0 | AK14: 0
A15: n4 | B15: 1 | C15: 1 | D15: 1 | E15: 2 | G15: 111 | H15: 93567 | I15: 3 | J15: 93567-3 | L15: 0 | M15: 1.1.1.2 | O15: 40863 | P15: EXAMES - MENSALISTA (COLETADO CAIXA - ENCARGOS COMPLEMENTARES) | Q15: 1 | R15: MES | S15: 215,56 | T15: 10 | U15: 10 | V15: 215,56 | AE15: 258,672 | AF15: 0 | AG15: 10 MES | AH15: 0 | AK15: 0
A16: n4 | B16: 1 | C16: 1 | D16: 1 | E16: 3 | G16: 111 | H16: 93567 | I16: 4 | J16: 93567-4 | L16: 0 | M16: 1.1.1.3 | O16: 40864 | P16: SEGURO - MENSALISTA (COLETADO CAIXA - ENCARGOS COMPLEMENTARES) | Q16: 1 | R16: MES | S16: 12,89 | T16: 10 | U16: 10 | V16: 12,89 | AE16: 15,468 | AF16: 0 | AG16: 10 MES | AH16: 0 | AK16: 0
A17: n4 | B17: 1 | C17: 1 | D17: 1 | E17: 4 | G17: 111 | H17: 93567 | I17: 5 | J17: 93567-5 | L17: 0 | M17: 1.1.1.4 | O17: 43474 | P17: FERRAMENTAS - FAMILIA ENGENHEIRO CIVIL - MENSALISTA (ENCARGOS COMPLEMENTARES - COLETADO CAIXA) | Q17: 1 | R17: MES | S17: 2,54 | T17: 10 | U17: 10 | V17: 2,54 | AE17: 3,048 | AF17: 0 | AG17: 10 MES | AH17: 0 | AK17: 0
A18: n4 | B18: 1 | C18: 1 | D18: 1 | E18: 5 | G18: 111 | H18: 93567 | I18: 6 | J18: 93567-6 | L18: 0 | M18: 1.1.1.5 | O18: 43498 | P18: EPI - FAMILIA ENGENHEIRO CIVIL - MENSALISTA (ENCARGOS COMPLEMENTARES - COLETADO CAIXA) | Q18: 1 | R18: MES | S18: 133,45 | T18: 10 | U18: 10 | V18: 133,45 | AE18: 160,14 | AF18: 0 | AG18: 10 MES | AH18: 0 | AK18: 0
A19: n4 | B19: 1 | C19: 1 | D19: 1 | E19: 6 | G19: 111 | H19: 93567 | I19: 7 | J19: 93567-7 | L19: 0 | M19: 1.1.1.6 | O19: 95417 | P19: CURSO DE CAPACITAÇÃO PARA ENGENHEIRO CIVIL DE OBRA PLENO (ENCARGOS COMPLEMENTARES) - MENSALISTA | Q19: 1 | R19: MES | S19: 255,03 | T19: 10 | U19: 10 | V19: 255,03 | AE19: 306,036 | AF19: 0 | AG19: 10 MES | AH19: 0 | AK19: 0
A20: n4 | B20: 1 | C20: 1 | D20: 1 | E20: 7 | G20: 111 | H20: 93567 | I20: 8 | J20: 93567-8 | L20: 0 | T20: 10 | AF20: 0 | AH20: 0 | AK20: 0
A21: n4 | B21: 1 | C21: 1 | D21: 1 | E21: 8 | G21: 111 | H21: 93567 | I21: 9 | J21: 93567-9 | L21: 0 | T21: 10 | AF21: 0 | AH21: 0 | AK21: 0
A22: n4 | B22: 1 | C22: 1 | D22: 1 | E22: 9 | G22: 111 | H22: 93567 | I22: 10 | J22: 93567-10 | L22: 0 | T22: 10 | AF22: 0 | AH22: 0 | AK22: 0
A23: n4 | B23: 1 | C23: 1 | D23: 1 | E23: 10 | G23: 111 | H23: 93567 | I23: 11 | J23: 93567-11 | L23: 0 | T23: 10 | AF23: 0 | AH23: 0 | AK23: 0
A24: n4 | B24: 1 | C24: 1 | D24: 1 | E24: 11 | G24: 111 | H24: 93567 | I24: 12 | J24: 93567-12 | L24: 0 | T24: 10 | AF24: 0 | AH24: 0 | AK24: 0
A25: n4 | B25: 1 | C25: 1 | D25: 1 | E25: 12 | G25: 111 | H25: 93567 | I25: 13 | J25: 93567-13 | L25: 0 | T25: 10 | AF25: 0 | AH25: 0 | AK25: 0
A26: n4 | B26: 1 | C26: 1 | D26: 1 | E26: 13 | G26: 111 | H26: 93567 | I26: 14 | J26: 93567-14 | L26: 0 | T26: 10 | AF26: 0 | AH26: 0 | AK26: 0
A27: n4 | B27: 1 | C27: 1 | D27: 1 | E27: 14 | G27: 111 | H27: 93567 | I27: 15 | J27: 93567-15 | L27: 0 | T27: 10 | AF27: 0 | AH27: 0 | AK27: 0
A28: n4 | B28: 1 | C28: 1 | D28: 1 | E28: 15 | G28: 111 | H28: 93567 | I28: 16 | J28: 93567-16 | L28: 0 | T28: 10 | AF28: 0 | AH28: 0 | AK28: 0
L29: 0
A30: n3 | B30: 1 | C30: 1 | D30: 2 | G30: 11 | L30: 0 | S30: 0 | AF30: 0 | AH30: 0 | AK30: 0
A31: n4 | B31: 1 | C31: 1 | D31: 2 | E31: 1 | G31: 112 | H31: 0 | I31: 2 | J31: 0-2 | L31: 0 | T31: 0 | AF31: 0 | AH31: 0 | AK31: 0
A32: n4 | B32: 1 | C32: 1 | D32: 2 | E32: 2 | G32: 112 | H32: 0 | I32: 3 | J32: 0-3 | L32: 0 | T32: 0 | AF32: 0 | AH32: 0 | AK32: 0
A33: n4 | B33: 1 | C33: 1 | D33: 2 | E33: 3 | G33: 112 | H33: 0 | I33: 4 | J33: 0-4 | L33: 0 | T33: 0 | AF33: 0 | AH33: 0 | AK33: 0
A34: n4 | B34: 1 | C34: 1 | D34: 2 | E34: 4 | G34: 112 | H34: 0 | I34: 5 | J34: 0-5 | L34: 0 | T34: 0 | AF34: 0 | AH34: 0 | AK34: 0
A35: n4 | B35: 1 | C35: 1 | D35: 2 | E35: 5 | G35: 112 | H35: 0 | I35: 6 | J35: 0-6 | L35: 0 | T35: 0 | AF35: 0 | AH35: 0 | AK35: 0
A36: n4 | B36: 1 | C36: 1 | D36: 2 | E36: 6 | G36: 112 | H36: 0 | I36: 7 | J36: 0-7 | L36: 0 | T36: 0 | AF36: 0 | AH36: 0 | AK36: 0
A37: n4 | B37: 1 | C37: 1 | D37: 2 | E37: 7 | G37: 112 | H37: 0 | I37: 8 | J37: 0-8 | L37: 0 | T37: 0 | AF37: 0 | AH37: 0 | AK37: 0
A38: n4 | B38: 1 | C38: 1 | D38: 2 | E38: 8 | G38: 112 | H38: 0 | I38: 9 | J38: 0-9 | L38: 0 | T38: 0 | AF38: 0 | AH38: 0 | AK38: 0
A39: n4 | B39: 1 | C39: 1 | D39: 2 | E39: 9 | G39: 112 | H39: 0 | I39: 10 | J39: 0-10 | L39: 0 | T39: 0 | AF39: 0 | AH39: 0 | AK39: 0
A40: n4 | B40: 1 | C40: 1 | D40: 2 | E40: 10 | G40: 112 | H40: 0 | I40: 11 | J40: 0-11 | L40: 0 | T40: 0 | AF40: 0 | AH40: 0 | AK40: 0
A41: n4 | B41: 1 | C41: 1 | D41: 2 | E41: 11 | G41: 112 | H41: 0 | I41: 12 | J41: 0-12 | L41: 0 | T41: 0 | AF41: 0 | AH41: 0 | AK41: 0
A42: n4 | B42: 1 | C42: 1 | D42: 2 | E42: 12 | G42: 112 | H42: 0 | I42: 13 | J42: 0-13 | L42: 0 | T42: 0 | AF42: 0 | AH42: 0 | AK42: 0
... A45: n4 | B45: 1 | C45: 1 | D45: 2 | E45: 15 | G45: 112 | H45: 0 | I45: 16 | J45: 0-16 | L45: 0 | T45: 0 | AF45: 0 | AH45: 0 | AK45: 0
L46: 0
...

Sheet Planilha1
B2: {=IFERROR(INDEX('ORÇ#1'!$A$1:$V$9999,SMALL(IF('ORÇ#1'!$A$1:$A$9999="n1",ROW('ORÇ#1'!$A$1:$A$9999)),ROW(A1)),6),"")} -> 1 | C2: {=IFERROR(INDEX('ORÇ#1'!$A$1:$V$9999,SMALL(IF('ORÇ#1'!$A$1:$A$9999="n1",ROW('ORÇ#1'!$A$1:$A$9999)),ROW(A1)),16),"")} -> CUSTOS INDIRETOS | D2: {=IFERROR(INDEX('ORÇ#1'!$A$1:$V$9999,SMALL(IF('ORÇ#1'!$A$1:$A$9999="n1",ROW('ORÇ#1'!$A$1:$A$9999)),ROW(A1)),22)*1,"")} -> 224917.9
B3: {=IFERROR(INDEX('ORÇ#1'!$A$1:$V$9999,SMALL(IF('ORÇ#1'!$A$1:$A$9999="n1",ROW('ORÇ#1'!$A$1:$A$9999)),ROW(A2)),6),"")} -> 2 | C3: {=IFERROR(INDEX('ORÇ#1'!$A$1:$V$9999,SMALL(IF('ORÇ#1'!$A$1:$A$9999="n1",ROW('ORÇ#1'!$A$1:$A$9999)),ROW(A2)),16),"")} -> SERVIÇOS PRELIMINARES | D3: {=IFERROR(INDEX('ORÇ#1'!$A$1:$V$9999,SMALL(IF('ORÇ#1'!$A$1:$A$9999="n1",ROW('ORÇ#1'!$A$1:$A$9999)),ROW(A2)),22)*1,"")} -> 79014.27
B4: {=IFERROR(INDEX('ORÇ#1'!$A$1:$V$9999,SMALL(IF('ORÇ#1'!$A$1:$A$9999="n1",ROW('ORÇ#1'!$A$1:$A$9999)),ROW(A3)),6),"")} -> 3 | C4: {=IFERROR(INDEX('ORÇ#1'!$A$1:$V$9999,SMALL(IF('ORÇ#1'!$A$1:$A$9999="n1",ROW('ORÇ#1'!$A$1:$A$9999)),ROW(A3)),16),"")} -> MOVIMENTAÇÃO DE TERRA | D4: {=IFERROR(INDEX('ORÇ#1'!$A$1:$V$9999,SMALL(IF('ORÇ#1'!$A$1:$A$9999="n1",ROW('ORÇ#1'!$A$1:$A$9999)),ROW(A3)),22)*1,"")} -> 3576.3
B5: {=IFERROR(INDEX('ORÇ#1'!$A$1:$V$9999,SMALL(IF('ORÇ#1'!$A$1:$A$9999="n1",ROW('ORÇ#1'!$A$1:$A$9999)),ROW(A4)),6),"")} -> 4 | C5: {=IFERROR(INDEX('ORÇ#1'!$A$1:$V$9999,SMALL(IF('ORÇ#1'!$A$1:$A$9999="n1",ROW('ORÇ#1'!$A$1:$A$9999)),ROW(A4)),16),"")} -> CONTENÇÕES | D5: {=IFERROR(INDEX('ORÇ#1'!$A$1:$V$9999,SMALL(IF('ORÇ#1'!$A$1:$A$9999="n1",ROW('ORÇ#1'!$A$1:$A$9999)),ROW(A4)),22)*1,"")} -> 18143.65
B6: {=IFERROR(INDEX('ORÇ#1'!$A$1:$V$9999,SMALL(IF('ORÇ#1'!$A$1:$A$9999="n1",ROW('ORÇ#1'!$A$1:$A$9999)),ROW(A5)),6),"")} -> 5 | C6: {=IFERROR(INDEX('ORÇ#1'!$A$1:$V$9999,SMALL(IF('ORÇ#1'!$A$1:$A$9999="n1",ROW('ORÇ#1'!$A$1:$A$9999)),ROW(A5)),16),"")} -> FUNDAÇÕES | D6: {=IFERROR(INDEX('ORÇ#1'!$A$1:$V$9999,SMALL(IF('ORÇ#1'!$A$1:$A$9999="n1",ROW('ORÇ#1'!$A$1:$A$9999)),ROW(A5)),22)*1,"")} -> 142139.33
B7: {=IFERROR(INDEX('ORÇ#1'!$A$1:$V$9999,SMALL(IF('ORÇ#1'!$A$1:$A$9999="n1",ROW('ORÇ#1'!$A$1:$A$9999)),ROW(A6)),6),"")} -> 6 | C7: {=IFERROR(INDEX('ORÇ#1'!$A$1:$V$9999,SMALL(IF('ORÇ#1'!$A$1:$A$9999="n1",ROW('ORÇ#1'!$A$1:$A$9999)),ROW(A6)),16),"")} -> ESTRUTURA | D7: {=IFERROR(INDEX('ORÇ#1'!$A$1:$V$9999,SMALL(IF('ORÇ#1'!$A$1:$A$9999="n1",ROW('ORÇ#1'!$A$1:$A$9999)),ROW(A6)),22)*1,"")} -> 1436404
B8: {=IFERROR(INDEX('ORÇ#1'!$A$1:$V$9999,SMALL(IF('ORÇ#1'!$A$1:$A$9999="n1",ROW('ORÇ#1'!$A$1:$A$9999)),ROW(A7)),6),"")} -> 7 | C8: {=IFERROR(INDEX('ORÇ#1'!$A$1:$V$9999,SMALL(IF('ORÇ#1'!$A$1:$A$9999="n1",ROW('ORÇ#1'!$A$1:$A$9999)),ROW(A7)),16),"")} -> ALVENARIAS | D8: {=IFERROR(INDEX('ORÇ#1'!$A$1:$V$9999,SMALL(IF('ORÇ#1'!$A$1:$A$9999="n1",ROW('ORÇ#1'!$A$1:$A$9999)),ROW(A7)),22)*1,"")} -> 324261.23
B9: {=IFERROR(INDEX('ORÇ#1'!$A$1:$V$9999,SMALL(IF('ORÇ#1'!$A$1:$A$9999="n1",ROW('ORÇ#1'!$A$1:$A$9999)),ROW(A8)),6),"")} -> 8 | C9: {=IFERROR(INDEX('ORÇ#1'!$A$1:$V$9999,SMALL(IF('ORÇ#1'!$A$1:$A$9999="n1",ROW('ORÇ#1'!$A$1:$A$9999)),ROW(A8)),16),"")} -> INSTALAÇÕES PREDIAIS | D9: {=IFERROR(INDEX('ORÇ#1'!$A$1:$V$9999,SMALL(IF('ORÇ#1'!$A$1:$A$9999="n1",ROW('ORÇ#1'!$A$1:$A$9999)),ROW(A8)),22)*1,"")} -> 2032618
B10: {=IFERROR(INDEX('ORÇ#1'!$A$1:$V$9999,SMALL(IF('ORÇ#1'!$A$1:$A$9999="n1",ROW('ORÇ#1'!$A$1:$A$9999)),ROW(A9)),6),"")} -> 9 | C10: {=IFERROR(INDEX('ORÇ#1'!$A$1:$V$9999,SMALL(IF('ORÇ#1'!$A$1:$A$9999="n1",ROW('ORÇ#1'!$A$1:$A$9999)),ROW(A9)),16),"")} -> PAVIMENTAÇÕES | D10: {=IFERROR(INDEX('ORÇ#1'!$A$1:$V$9999,SMALL(IF('ORÇ#1'!$A$1:$A$9999="n1",ROW('ORÇ#1'!$A$1:$A$9999)),ROW(A9)),22)*1,"")} -> 86827.514
B11: {=IFERROR(INDEX('ORÇ#1'!$A$1:$V$9999,SMALL(IF('ORÇ#1'!$A$1:$A$9999="n1",ROW('ORÇ#1'!$A$1:$A$9999)),ROW(A10)),6),"")} -> 10 | C11: {=IFERROR(INDEX('ORÇ#1'!$A$1:$V$9999,SMALL(IF('ORÇ#1'!$A$1:$A$9999="n1",ROW('ORÇ#1'!$A$1:$A$9999)),ROW(A10)),16),"")} -> REVESTIMENTOS | D11: {=IFERROR(INDEX('ORÇ#1'!$A$1:$V$9999,SMALL(IF('ORÇ#1'!$A$1:$A$9999="n1",ROW('ORÇ#1'!$A$1:$A$9999)),ROW(A10)),22)*1,"")} -> 826939.34
B12: {=IFERROR(INDEX('ORÇ#1'!$A$1:$V$9999,SMALL(IF('ORÇ#1'!$A$1:$A$9999="n1",ROW('ORÇ#1'!$A$1:$A$9999)),ROW(A11)),6),"")} -> 11 | C12: {=IFERROR(INDEX('ORÇ#1'!$A$1:$V$9999,SMALL(IF('ORÇ#1'!$A$1:$A$9999="n1",ROW('ORÇ#1'!$A$1:$A$9999)),ROW(A11)),16),"")} -> IMPERMEABILIZAÇÕES | D12: {=IFERROR(INDEX('ORÇ#1'!$A$1:$V$9999,SMALL(IF('ORÇ#1'!$A$1:$A$9999="n1",ROW('ORÇ#1'!$A$1:$A$9999)),ROW(A11)),22)*1,"")} -> 135014.29
B13: {=IFERROR(INDEX('ORÇ#1'!$A$1:$V$9999,SMALL(IF('ORÇ#1'!$A$1:$A$9999="n1",ROW('ORÇ#1'!$A$1:$A$9999)),ROW(A12)),6),"")} -> 12 | C13: {=IFERROR(INDEX('ORÇ#1'!$A$1:$V$9999,SMALL(IF('ORÇ#1'!$A$1:$A$9999="n1",ROW('ORÇ#1'!$A$1:$A$9999)),ROW(A12)),16),"")} -> GRANITOS | D13: {=IFERROR(INDEX('ORÇ#1'!$A$1:$V$9999,SMALL(IF('ORÇ#1'!$A$1:$A$9999="n1",ROW('ORÇ#1'!$A$1:$A$9999)),ROW(A12)),22)*1,"")} -> 107778.47
... B31: {=IFERROR(INDEX('ORÇ#1'!$A$1:$V$9999,SMALL(IF('ORÇ#1'!$A$1:$A$9999="n1",ROW('ORÇ#1'!$A$1:$A$9999)),ROW(A30)),6),"")} | C31: {=IFERROR(INDEX('ORÇ#1'!$A$1:$V$9999,SMALL(IF('ORÇ#1'!$A$1:$A$9999="n1",ROW('ORÇ#1'!$A$1:$A$9999)),ROW(A30)),16),"")} | D31: {=IFERROR(INDEX('ORÇ#1'!$A$1:$V$9999,SMALL(IF('ORÇ#1'!$A$1:$A$9999="n1",ROW('ORÇ#1'!$A$1:$A$9999)),ROW(A30)),22)*1,"")}

Sheet SIMULAÇÃO 01
B6: ANÁLISE DE VIABILIDADE FINANCEIRA PRELIMINAR | AR6: SIMULAÇÃO 01
B8: INFORMAÇÕES DO EMPREENDIMENTO
B10: OBRA | H10: Ed. Curupira | EW Esteves Construções | T10: CIDADE / UF | Z10: Ribeirão Preto / SP | AI10: PREÇO M² | AO10: 6682.9332
B12: MAPA DAS UNIDADES
B14: TIPOLOGIA | K14: ÁREA PRIVATIVA | T14: QUANT. | Z14: PREÇO M² | AI14: VALOR / UNIDADE | AR14: PERMUTA
B15: 1º Pav. Final 1 e 3 | K15: 73 | T15: 2 | Z15: =IF(B15<>"",$AO$10,"") -> 6682.9332 | AI15: =IF(K15=""," ",IF(Z15=""," ",Z15*K15)) -> 487854.12
B16: 1º Pav. Final 2 e 4 | K16: 70 | T16: 2 | Z16: =IF(B16<>"",$AO$10,"") -> 6682.9332 | AI16: =IF(K16=""," ",IF(Z16=""," ",Z16*K16)) -> 467805.32
B17: 2º Pav. Final 1 e 3 | K17: 73 | T17: 2 | Z17: =IF(B17<>"",$AO$10,"") -> 6682.9332 | AI17: =IF(K17=""," ",IF(Z17=""," ",Z17*K17)) -> 487854.12
B18: 2º Pav. Final 2 e 4 | K18: 70 | T18: 2 | Z18: =IF(B18<>"",$AO$10,"") -> 6682.9332 | AI18: =IF(K18=""," ",IF(Z18=""," ",Z18*K18)) -> 467805.32
B19: 3º Pav. Final 1 e 3 | K19: 73 | T19: 2 | Z19: =IF(B19<>"",$AO$10,"") -> 6682.9332 | AI19: =IF(K19=""," ",IF(Z19=""," ",Z19*K19)) -> 487854.12
B20: 3º Pav. Final 2 e 4 | K20: 70 | T20: 2 | Z20: =IF(B20<>"",$AO$10,"") -> 6682.9332 | AI20: =IF(K20=""," ",IF(Z20=""," ",Z20*K20)) -> 467805.32
B21: 4º Pav. Final 1 e 3 | K21: 73 | T21: 2 | Z21: =IF(B21<>"",$AO$10,"") -> 6682.9332 | AI21: =IF(K21=""," ",IF(Z21=""," ",Z21*K21)) -> 487854.12
B22: 4º Pav. Final 2 e 4 | K22: 70 | T22: 2 | Z22: =IF(B22<>"",$AO$10,"") -> 6682.9332 | AI22: =IF(K22=""," ",IF(Z22=""," ",Z22*K22)) -> 467805.32
B23: 5º Pav. Final 1 e 3 | K23: 73 | T23: 2 | Z23: =IF(B23<>"",$AO$10,"") -> 6682.9332 | AI23: =IF(K23=""," ",IF(Z23=""," ",Z23*K23)) -> 487854.12
B24: 5º Pav. Final 2 e 4 | K24: 70 | T24: 2 | Z24: =IF(B24<>"",$AO$10,"") -> 6682.9332 | AI24: =IF(K24=""," ",IF(Z24=""," ",Z24*K24)) -> 467805.32
Z25: =IF(B25<>"",$AO$10,"") | AI25: =IF(K25=""," ",IF(Z25=""," ",Z25*K25))
Z26: =IF(B26<>"",$AO$10,"") | AI26: =IF(K26=""," ",IF(Z26=""," ",Z26*K26))
B28: LINHA DO TEMPO | AI28: ESCALA: | AR28: MENSAL
B30: INÍCIO | F30: 45170 | J30: =IF(F30="","",F30) -> 45170 | K30: =IFERROR(DATE(YEAR(J30),IF($AR$28="MENSAL",MONTH(J30)+1,MONTH(J30)+2),1),"") -> 45200 | L30: =IFERROR(DATE(YEAR(K30),IF($AR$28="MENSAL",MONTH(K30)+1,MONTH(K30)+2),1),"") -> 45231 | M30: =IFERROR(DATE(YEAR(L30),IF($AR$28="MENSAL",MONTH(L30)+1,MONTH(L30)+2),1),"") -> 45261 | N30: =IFERROR(DATE(YEAR(M30),IF($AR$28="MENSAL",MONTH(M30)+1,MONTH(M30)+2),1),"") -> 45292 | O30: =IFERROR(DATE(YEAR(N30),IF($AR$28="MENSAL",MONTH(N30)+1,MONTH(N30)+2),1),"") -> 45323 | P30: =IFERROR(DATE(YEAR(O30),IF($AR$28="MENSAL",MONTH(O30)+1,MONTH(O30)+2),1),"") -> 45352 | Q30: =IFERROR(DATE(YEAR(P30),IF($AR$28="MENSAL",MONTH(P30)+1,MONTH(P30)+2),1),"") -> 45383 | R30: =IFERROR(DATE(YEAR(Q30),IF($AR$28="MENSAL",MONTH(Q30)+1,MONTH(Q30)+2),1),"") -> 45413 | ... AW30: =IFERROR(DATE(YEAR(AV30),IF($AR$28="MENSAL",MONTH(AV30)+1,MONTH(AV30)+2),1),"") -> 46357
B32: START VENDAS | F32: 6
B34: ETAPA | F34: MESES | AY34: I | AZ34: T
B35: Viabilidade | F35: 2 | J35: =IF(AND(J$30>=$AY35,J$30<=$AZ35),1,0) -> 1 | K35: =IF(AND(K$30>=$AY35,K$30<=$AZ35),1,0) -> 1 | L35: =IF(AND(L$30>=$AY35,L$30<=$AZ35),1,0) -> 0 | M35: =IF(AND(M$30>=$AY35,M$30<=$AZ35),1,0) -> 0 | N35: =IF(AND(N$30>=$AY35,N$30<=$AZ35),1,0) -> 0 | O35: =IF(AND(O$30>=$AY35,O$30<=$AZ35),1,0) -> 0 | P35: =IF(AND(P$30>=$AY35,P$30<=$AZ35),1,0) -> 0 | Q35: =IF(AND(Q$30>=$AY35,Q$30<=$AZ35),1,0) -> 0 | ... AW35: =IF(AND(AW$30>=$AY35,AW$30<=$AZ35),1,0) -> 0 | AY35: =F30 -> 45170 | AZ35: =DATE(YEAR(AY35),MONTH(AY35)+F35-1,1) -> 45200
B36: Aprovação | F36: 2 | J36: =IF(AND(J$30>=$AY36,J$30<=$AZ36),1,0) -> 0 | K36: =IF(AND(K$30>=$AY36,K$30<=$AZ36),1,0) -> 0 | L36: =IF(AND(L$30>=$AY36,L$30<=$AZ36),1,0) -> 1 | M36: =IF(AND(M$30>=$AY36,M$30<=$AZ36),1,0) -> 1 | N36: =IF(AND(N$30>=$AY36,N$30<=$AZ36),1,0) -> 0 | O36: =IF(AND(O$30>=$AY36,O$30<=$AZ36),1,0) -> 0 | P36: =IF(AND(P$30>=$AY36,P$30<=$AZ36),1,0) -> 0 | Q36: =IF(AND(Q$30>=$AY36,Q$30<=$AZ36),1,0) -> 0 | ... AW36: =IF(AND(AW$30>=$AY36,AW$30<=$AZ36),1,0) -> 0 | AY36: =DATE(YEAR(AZ35),MONTH(AZ35)+1,1) -> 45231 | AZ36: =DATE(YEAR(AY36),MONTH(AY36)+F36-1,1) -> 45261
B37: Vendas | F37: 30 | J37: =IF(AND(J$30>=$AY37,J$30<=$AZ37),1,0) -> 0 | K37: =IF(AND(K$30>=$AY37,K$30<=$AZ37),1,0) -> 0 | L37: =IF(AND(L$30>=$AY37,L$30<=$AZ37),1,0) -> 0 | M37: =IF(AND(M$30>=$AY37,M$30<=$AZ37),1,0) -> 0 | N37: =IF(AND(N$30>=$AY37,N$30<=$AZ37),1,0) -> 1 | O37: =IF(AND(O$30>=$AY37,O$30<=$AZ37),1,0) -> 1 | P37: =IF(AND(P$30>=$AY37,P$30<=$AZ37),1,0) -> 1 | Q37: =IF(AND(Q$30>=$AY37,Q$30<=$AZ37),1,0) -> 1 | ... AW37: =IF(AND(AW$30>=$AY37,AW$30<=$AZ37),1,0) -> 0 | AY37: =DATE(YEAR(AZ36),MONTH(AZ36)+1,1) -> 45292 | AZ37: =DATE(YEAR(AY37),MONTH(AY37)+F37-1,1) -> 46174
B38: Obras | F38: 24 | J38: =IF(AND(J$30>=$AY38,J$30<=$AZ38),1,0) -> 0 | K38: =IF(AND(K$30>=$AY38,K$30<=$AZ38),1,0) -> 0 | L38: =IF(AND(L$30>=$AY38,L$30<=$AZ38),1,0) -> 0 | M38: =IF(AND(M$30>=$AY38,M$30<=$AZ38),1,0) -> 0 | N38: =IF(AND(N$30>=$AY38,N$30<=$AZ38),1,0) -> 0 | O38: =IF(AND(O$30>=$AY38,O$30<=$AZ38),1,0) -> 0 | P38: =IF(AND(P$30>=$AY38,P$30<=$AZ38),1,0) -> 0 | Q38: =IF(AND(Q$30>=$AY38,Q$30<=$AZ38),1,0) -> 0 | ... AW38: =IF(AND(AW$30>=$AY38,AW$30<=$AZ38),1,0) -> 0 | AY38: =DATE(YEAR(AY37),MONTH(AY37)+F32,1) -> 45474 | AZ38: =DATE(YEAR(AY38),MONTH(AY38)+F38-1,1) -> 46174
B39: Legalização | F39: 2 | J39: =IF(AND(J$30>=$AY39,J$30<=$AZ39),1,0) -> 0 | K39: =IF(AND(K$30>=$AY39,K$30<=$AZ39),1,0) -> 0 | L39: =IF(AND(L$30>=$AY39,L$30<=$AZ39),1,0) -> 0 | M39: =IF(AND(M$30>=$AY39,M$30<=$AZ39),1,0) -> 0 | N39: =IF(AND(N$30>=$AY39,N$30<=$AZ39),1,0) -> 0 | O39: =IF(AND(O$30>=$AY39,O$30<=$AZ39),1,0) -> 0 | P39: =IF(AND(P$30>=$AY39,P$30<=$AZ39),1,0) -> 0 | Q39: =IF(AND(Q$30>=$AY39,Q$30<=$AZ39),1,0) -> 0 | ... AW39: =IF(AND(AW$30>=$AY39,AW$30<=$AZ39),1,0) -> 0 | AY39: =DATE(YEAR(AZ38),MONTH(AZ38)+1,1) -> 46204 | AZ39: =DATE(YEAR(AY39),MONTH(AY39)+F39-1,1) -> 46235
B41: QUADRO RESUMO
J43: UNIDADES | R43: ÁREA PRIVATIVA | AH43: VALOR GERAL DE VENDA (VGV)
B44: Vendável | J44: =J46-J45 -> 20 | R44: =R46-R45 -> 1430 | AB44: =IFERROR(R44/R46,"") -> 1 | AH44: =AH46-AH45 -> 9556594.4 | AR44: =IFERROR(AH44/AH46,"") -> 1
B45: Permuta | J45: =SUM(AR15:AW26) -> 0 | R45: =SUMPRODUCT(K15:K26,AR15:AR26) -> 0 | AB45: =IFERROR(R45/R46,"") -> 0 | AH45: =SUMPRODUCT(K15:K26,AR15:AR26,Z15:Z26) -> 0 | AR45: =IFERROR(AH45/AH46,"") -> 0
B46: TOTAL | J46: =SUM(T15:Y26) -> 20 | R46: =SUMPRODUCT(K15:K26,T15:T26) -> 1430 | AH46: =SUMPRODUCT(K15:K26,T15:T26,Z15:Z26) -> 9556594.4
B48: ÁREA DO LOTE | J48: 500 | Z48: EFICIÊNCIA | AH48: C.A.
B49: ÁREA TOTAL CONSTRUÍDA | J49: 2399.77 | Z49: =IFERROR(R46/J49,"") -> 0.59589044 | AH49: =IFERROR(J50/J48,"") -> 2.955
B50: ÁREA COMPUTÁVEL | J50: 1477.5
B52: LOTE
B54: PERMUTA | J54: =AH45 -> 0
B55: PAGAMENTO | J55: 800000 | Z55: CUSTO BASE
B56: PERMUTA FINANCEIRA | J56: 0 | Z56: =SUM(J54:Q57) -> 800000
B57: PERMUTA FÍSICA FORA | J57: 0 | Z57: =IFERROR(Z56/J48,"") -> 1600
B58: COMISSÃO | J58: 0 | N58: =(SUM(J54:K57))*J58 -> 0
...

Sheet SIMULAÇÃO 02
B6: ANÁLISE DE VIABILIDADE FINANCEIRA PRELIMINAR | AR6: SIMULAÇÃO 02
B8: INFORMAÇÕES DO EMPREENDIMENTO
B10: OBRA | H10: ='SIMULAÇÃO 01'!H10 -> Ed. Curupira | EW Esteves Construções | T10: CIDADE / UF | Z10: ='SIMULAÇÃO 01'!Z10 -> Ribeirão Preto / SP | AI10: PREÇO M² | AO10: ='SIMULAÇÃO 01'!AO10 -> 6682.9332
B12: MAPA DAS UNIDADES
B14: TIPOLOGIA | K14: ÁREA PRIVATIVA | T14: QUANT. | Z14: PREÇO M² | AI14: VALOR / UNIDADE | AR14: PERMUTA
Z15: =IF(B15<>"",$AO$10,"") | AI15: =IF(K15=""," ",IF(Z15=""," ",Z15*K15))
Z16: =IF(B16<>"",$AO$10,"") | AI16: =IF(K16=""," ",IF(Z16=""," ",Z16*K16))
Z17: =IF(B17<>"",$AO$10,"") | AI17: =IF(K17=""," ",IF(Z17=""," ",Z17*K17))
Z18: =IF(B18<>"",$AO$10,"") | AI18: =IF(K18=""," ",IF(Z18=""," ",Z18*K18))
Z19: =IF(B19<>"",$AO$10,"") | AI19: =IF(K19=""," ",IF(Z19=""," ",Z19*K19))
Z20: =IF(B20<>"",$AO$10,"") | AI20: =IF(K20=""," ",IF(Z20=""," ",Z20*K20))
Z21: =IF(B21<>"",$AO$10,"") | AI21: =IF(K21=""," ",IF(Z21=""," ",Z21*K21))
Z22: =IF(B22<>"",$AO$10,"") | AI22: =IF(K22=""," ",IF(Z22=""," ",Z22*K22))
Z23: =IF(B23<>"",$AO$10,"") | AI23: =IF(K23=""," ",IF(Z23=""," ",Z23*K23))
Z24: =IF(B24<>"",$AO$10,"") | AI24: =IF(K24=""," ",IF(Z24=""," ",Z24*K24))
Z25: =IF(B25<>"",$AO$10,"") | AI25: =IF(K25=""," ",IF(Z25=""," ",Z25*K25))
Z26: =IF(B26<>"",$AO$10,"") | AI26: =IF(K26=""," ",IF(Z26=""," ",Z26*K26))
B28: LINHA DO TEMPO | AI28: ESCALA: | AR28: MENSAL
B30: INÍCIO | J30: =IF(F30="","",F30) | K30: =IFERROR(DATE(YEAR(J30),IF($AR$28="MENSAL",MONTH(J30)+1,MONTH(J30)+2),1),"") | L30: =IFERROR(DATE(YEAR(K30),IF($AR$28="MENSAL",MONTH(K30)+1,MONTH(K30)+2),1),"") | M30: =IFERROR(DATE(YEAR(L30),IF($AR$28="MENSAL",MONTH(L30)+1,MONTH(L30)+2),1),"") | N30: =IFERROR(DATE(YEAR(M30),IF($AR$28="MENSAL",MONTH(M30)+1,MONTH(M30)+2),1),"") | O30: =IFERROR(DATE(YEAR(N30),IF($AR$28="MENSAL",MONTH(N30)+1,MONTH(N30)+2),1),"") | P30: =IFERROR(DATE(YEAR(O30),IF($AR$28="MENSAL",MONTH(O30)+1,MONTH(O30)+2),1),"") | Q30: =IFERROR(DATE(YEAR(P30),IF($AR$28="MENSAL",MONTH(P30)+1,MONTH(P30)+2),1),"") | R30: =IFERROR(DATE(YEAR(Q30),IF($AR$28="MENSAL",MONTH(Q30)+1,MONTH(Q30)+2),1),"") | ... AW30: =IFERROR(DATE(YEAR(AV30),IF($AR$28="MENSAL",MONTH(AV30)+1,MONTH(AV30)+2),1),"")
B32: START VENDAS
B34: ETAPA | F34: MESES | AY34: I | AZ34: T
B35: Viabilidade | J35: =IF(AND(J$30>=$AY35,J$30<=$AZ35),1,0) -> 0 | K35: =IF(AND(K$30>=$AY35,K$30<=$AZ35),1,0) -> 0 | L35: =IF(AND(L$30>=$AY35,L$30<=$AZ35),1,0) -> 0 | M35: =IF(AND(M$30>=$AY35,M$30<=$AZ35),1,0) -> 0 | N35: =IF(AND(N$30>=$AY35,N$30<=$AZ35),1,0) -> 0 | O35: =IF(AND(O$30>=$AY35,O$30<=$AZ35),1,0) -> 0 | P35: =IF(AND(P$30>=$AY35,P$30<=$AZ35),1,0) -> 0 | Q35: =IF(AND(Q$30>=$AY35,Q$30<=$AZ35),1,0) -> 0 | ... AW35: =IF(AND(AW$30>=$AY35,AW$30<=$AZ35),1,0) -> 0 | AY35: =F30 -> 0 | AZ35: =DATE(YEAR(AY35),MONTH(AY35)+F35,1) -> 1
B36: Aprovação | J36: =IF(AND(J$30>=$AY36,J$30<=$AZ36),1,0) -> 0 | K36: =IF(AND(K$30>=$AY36,K$30<=$AZ36),1,0) -> 0 | L36: =IF(AND(L$30>=$AY36,L$30<=$AZ36),1,0) -> 0 | M36: =IF(AND(M$30>=$AY36,M$30<=$AZ36),1,0) -> 0 | N36: =IF(AND(N$30>=$AY36,N$30<=$AZ36),1,0) -> 0 | O36: =IF(AND(O$30>=$AY36,O$30<=$AZ36),1,0) -> 0 | P36: =IF(AND(P$30>=$AY36,P$30<=$AZ36),1,0) -> 0 | Q36: =IF(AND(Q$30>=$AY36,Q$30<=$AZ36),1,0) -> 0 | ... AW36: =IF(AND(AW$30>=$AY36,AW$30<=$AZ36),1,0) -> 0 | AY36: =AZ35 -> 1 | AZ36: =DATE(YEAR(AY36),MONTH(AY36)+F36,1) -> 1
B37: Vendas | J37: =IF(AND(J$30>=$AY37,J$30<=$AZ37),1,0) -> 0 | K37: =IF(AND(K$30>=$AY37,K$30<=$AZ37),1,0) -> 0 | L37: =IF(AND(L$30>=$AY37,L$30<=$AZ37),1,0) -> 0 | M37: =IF(AND(M$30>=$AY37,M$30<=$AZ37),1,0) -> 0 | N37: =IF(AND(N$30>=$AY37,N$30<=$AZ37),1,0) -> 0 | O37: =IF(AND(O$30>=$AY37,O$30<=$AZ37),1,0) -> 0 | P37: =IF(AND(P$30>=$AY37,P$30<=$AZ37),1,0) -> 0 | Q37: =IF(AND(Q$30>=$AY37,Q$30<=$AZ37),1,0) -> 0 | ... AW37: =IF(AND(AW$30>=$AY37,AW$30<=$AZ37),1,0) -> 0 | AY37: =AZ36 -> 1 | AZ37: =DATE(YEAR(AY37),MONTH(AY37)+F37,1) -> 1
B38: Obras | J38: =IF(AND(J$30>=$AY38,J$30<=$AZ38),1,0) -> 0 | K38: =IF(AND(K$30>=$AY38,K$30<=$AZ38),1,0) -> 0 | L38: =IF(AND(L$30>=$AY38,L$30<=$AZ38),1,0) -> 0 | M38: =IF(AND(M$30>=$AY38,M$30<=$AZ38),1,0) -> 0 | N38: =IF(AND(N$30>=$AY38,N$30<=$AZ38),1,0) -> 0 | O38: =IF(AND(O$30>=$AY38,O$30<=$AZ38),1,0) -> 0 | P38: =IF(AND(P$30>=$AY38,P$30<=$AZ38),1,0) -> 0 | Q38: =IF(AND(Q$30>=$AY38,Q$30<=$AZ38),1,0) -> 0 | ... AW38: =IF(AND(AW$30>=$AY38,AW$30<=$AZ38),1,0) -> 0 | AY38: =DATE(YEAR(AY37),MONTH(AY37)+F32,1) -> 1 | AZ38: =DATE(YEAR(AY38),MONTH(AY38)+F38,1) -> 1
B39: Legalização | J39: =IF(AND(J$30>=$AY39,J$30<=$AZ39),1,0) -> 0 | K39: =IF(AND(K$30>=$AY39,K$30<=$AZ39),1,0) -> 0 | L39: =IF(AND(L$30>=$AY39,L$30<=$AZ39),1,0) -> 0 | M39: =IF(AND(M$30>=$AY39,M$30<=$AZ39),1,0) -> 0 | N39: =IF(AND(N$30>=$AY39,N$30<=$AZ39),1,0) -> 0 | O39: =IF(AND(O$30>=$AY39,O$30<=$AZ39),1,0) -> 0 | P39: =IF(AND(P$30>=$AY39,P$30<=$AZ39),1,0) -> 0 | Q39: =IF(AND(Q$30>=$AY39,Q$30<=$AZ39),1,0) -> 0 | ... AW39: =IF(AND(AW$30>=$AY39,AW$30<=$AZ39),1,0) -> 0 | AY39: =AZ38 -> 1 | AZ39: =DATE(YEAR(AY39),MONTH(AY39)+F39,1) -> 1
B41: QUADRO RESUMO
J43: UNIDADES | R43: ÁREA PRIVATIVA | AH43: VALOR GERAL DE VENDA (VGV)
B44: Vendável | J44: =J46-J45 -> 0 | R44: =R46-R45 -> 0 | AB44: =IFERROR(R44/R46,"") | AH44: =AH46-AH45 -> 0 | AR44: =IFERROR(AH44/AH46,"")
B45: Permuta | J45: =SUM(AR15:AW26) -> 0 | R45: =SUMPRODUCT(K15:K26,AR15:AR26) -> 0 | AB45: =IFERROR(R45/R46,"") | AH45: =SUMPRODUCT(K15:K26,AR15:AR26,Z15:Z26) -> 0 | AR45: =IFERROR(AH45/AH46,"")
B46: TOTAL | J46: =SUM(T15:Y26) -> 0 | R46: =SUMPRODUCT(K15:K26,T15:T26) -> 0 | AH46: =SUMPRODUCT(K15:K26,T15:T26,Z15:Z26) -> 0
B48: ÁREA DO LOTE | Z48: EFICIÊNCIA | AH48: C.A.
B49: ÁREA TOTAL CONSTRUÍDA | Z49: =IFERROR(R46/J49,"") | AH49: =IFERROR(J50/J48,"")
B50: ÁREA COMPUTÁVEL
B52: LOTE
B54: PERMUTA | J54: =AH45 -> 0
B55: PAGAMENTO | Z55: CUSTO BASE
B56: PERMUTA FINANCEIRA | Z56: =SUM(J54:Q57) -> 0
B57: PERMUTA FÍSICA FORA | Z57: =IFERROR(Z56/J48,"")
B58: COMISSÃO | N58: =(SUM(J54:K57))*J58 -> 0
...

Sheet SIMULAÇÃO 03
B6: ANÁLISE DE VIABILIDADE FINANCEIRA PRELIMINAR | AR6: SIMULAÇÃO 03
B8: INFORMAÇÕES DO EMPREENDIMENTO
B10: OBRA | H10: ='SIMULAÇÃO 01'!H10 -> Ed. Curupira | EW Esteves Construções | T10: CIDADE / UF | Z10: ='SIMULAÇÃO 01'!Z10 -> Ribeirão Preto / SP | AI10: PREÇO M² | AO10: ='SIMULAÇÃO 01'!AO10 -> 6682.9332
B12: MAPA DAS UNIDADES
B14: TIPOLOGIA | K14: ÁREA PRIVATIVA | T14: QUANT. | Z14: PREÇO M² | AI14: VALOR / UNIDADE | AR14: PERMUTA
Z15: =IF(B15<>"",$AO$10,"") | AI15: =IF(K15=""," ",IF(Z15=""," ",Z15*K15))
Z16: =IF(B16<>"",$AO$10,"") | AI16: =IF(K16=""," ",IF(Z16=""," ",Z16*K16))
Z17: =IF(B17<>"",$AO$10,"") | AI17: =IF(K17=""," ",IF(Z17=""," ",Z17*K17))
Z18: =IF(B18<>"",$AO$10,"") | AI18: =IF(K18=""," ",IF(Z18=""," ",Z18*K18))
Z19: =IF(B19<>"",$AO$10,"") | AI19: =IF(K19=""," ",IF(Z19=""," ",Z19*K19))
Z20: =IF(B20<>"",$AO$10,"") | AI20: =IF(K20=""," ",IF(Z20=""," ",Z20*K20))
Z21: =IF(B21<>"",$AO$10,"") | AI21: =IF(K21=""," ",IF(Z21=""," ",Z21*K21))
Z22: =IF(B22<>"",$AO$10,"") | AI22: =IF(K22=""," ",IF(Z22=""," ",Z22*K22))
Z23: =IF(B23<>"",$AO$10,"") | AI23: =IF(K23=""," ",IF(Z23=""," ",Z23*K23))
Z24: =IF(B24<>"",$AO$10,"") | AI24: =IF(K24=""," ",IF(Z24=""," ",Z24*K24))
Z25: =IF(B25<>"",$AO$10,"") | AI25: =IF(K25=""," ",IF(Z25=""," ",Z25*K25))
Z26: =IF(B26<>"",$AO$10,"") | AI26: =IF(K26=""," ",IF(Z26=""," ",Z26*K26))
B28: LINHA DO TEMPO | AI28: ESCALA: | AR28: MENSAL
B30: INÍCIO | J30: =IF(F30="","",F30) | K30: =IFERROR(DATE(YEAR(J30),IF($AR$28="MENSAL",MONTH(J30)+1,MONTH(J30)+2),1),"") | L30: =IFERROR(DATE(YEAR(K30),IF($AR$28="MENSAL",MONTH(K30)+1,MONTH(K30)+2),1),"") | M30: =IFERROR(DATE(YEAR(L30),IF($AR$28="MENSAL",MONTH(L30)+1,MONTH(L30)+2),1),"") | N30: =IFERROR(DATE(YEAR(M30),IF($AR$28="MENSAL",MONTH(M30)+1,MONTH(M30)+2),1),"") | O30: =IFERROR(DATE(YEAR(N30),IF($AR$28="MENSAL",MONTH(N30)+1,MONTH(N30)+2),1),"") | P30: =IFERROR(DATE(YEAR(O30),IF($AR$28="MENSAL",MONTH(O30)+1,MONTH(O30)+2),1),"") | Q30: =IFERROR(DATE(YEAR(P30),IF($AR$28="MENSAL",MONTH(P30)+1,MONTH(P30)+2),1),"") | R30: =IFERROR(DATE(YEAR(Q30),IF($AR$28="MENSAL",MONTH(Q30)+1,MONTH(Q30)+2),1),"") | ... AW30: =IFERROR(DATE(YEAR(AV30),IF($AR$28="MENSAL",MONTH(AV30)+1,MONTH(AV30)+2),1),"")
B32: START VENDAS
B34: ETAPA | F34: MESES | AY34: I | AZ34: T
B35: Viabilidade | J35: =IF(AND(J$30>=$AY35,J$30<=$AZ35),1,0) -> 0 | K35: =IF(AND(K$30>=$AY35,K$30<=$AZ35),1,0) -> 0 | L35: =IF(AND(L$30>=$AY35,L$30<=$AZ35),1,0) -> 0 | M35: =IF(AND(M$30>=$AY35,M$30<=$AZ35),1,0) -> 0 | N35: =IF(AND(N$30>=$AY35,N$30<=$AZ35),1,0) -> 0 | O35: =IF(AND(O$30>=$AY35,O$30<=$AZ35),1,0) -> 0 | P35: =IF(AND(P$30>=$AY35,P$30<=$AZ35),1,0) -> 0 | Q35: =IF(AND(Q$30>=$AY35,Q$30<=$AZ35),1,0) -> 0 | ... AW35: =IF(AND(AW$30>=$AY35,AW$30<=$AZ35),1,0) -> 0 | AY35: =F30 -> 0 | AZ35: =DATE(YEAR(AY35),MONTH(AY35)+F35,1) -> 1
B36: Aprovação | J36: =IF(AND(J$30>=$AY36,J$30<=$AZ36),1,0) -> 0 | K36: =IF(AND(K$30>=$AY36,K$30<=$AZ36),1,0) -> 0 | L36: =IF(AND(L$30>=$AY36,L$30<=$AZ36),1,0) -> 0 | M36: =IF(AND(M$30>=$AY36,M$30<=$AZ36),1,0) -> 0 | N36: =IF(AND(N$30>=$AY36,N$30<=$AZ36),1,0) -> 0 | O36: =IF(AND(O$30>=$AY36,O$30<=$AZ36),1,0) -> 0 | P36: =IF(AND(P$30>=$AY36,P$30<=$AZ36),1,0) -> 0 | Q36: =IF(AND(Q$30>=$AY36,Q$30<=$AZ36),1,0) -> 0 | ... AW36: =IF(AND(AW$30>=$AY36,AW$30<=$AZ36),1,0) -> 0 | AY36: =AZ35 -> 1 | AZ36: =DATE(YEAR(AY36),MONTH(AY36)+F36,1) -> 1
B37: Vendas | J37: =IF(AND(J$30>=$AY37,J$30<=$AZ37),1,0) -> 0 | K37: =IF(AND(K$30>=$AY37,K$30<=$AZ37),1,0) -> 0 | L37: =IF(AND(L$30>=$AY37,L$30<=$AZ37),1,0) -> 0 | M37: =IF(AND(M$30>=$AY37,M$30<=$AZ37),1,0) -> 0 | N37: =IF(AND(N$30>=$AY37,N$30<=$AZ37),1,0) -> 0 | O37: =IF(AND(O$30>=$AY37,O$30<=$AZ37),1,0) -> 0 | P37: =IF(AND(P$30>=$AY37,P$30<=$AZ37),1,0) -> 0 | Q37: =IF(AND(Q$30>=$AY37,Q$30<=$AZ37),1,0) -> 0 | ... AW37: =IF(AND(AW$30>=$AY37,AW$30<=$AZ37),1,0) -> 0 | AY37: =AZ36 -> 1 | AZ37: =DATE(YEAR(AY37),MONTH(AY37)+F37,1) -> 1
B38: Obras | J38: =IF(AND(J$30>=$AY38,J$30<=$AZ38),1,0) -> 0 | K38: =IF(AND(K$30>=$AY38,K$30<=$AZ38),1,0) -> 0 | L38: =IF(AND(L$30>=$AY38,L$30<=$AZ38),1,0) -> 0 | M38: =IF(AND(M$30>=$AY38,M$30<=$AZ38),1,0) -> 0 | N38: =IF(AND(N$30>=$AY38,N$30<=$AZ38),1,0) -> 0 | O38: =IF(AND(O$30>=$AY38,O$30<=$AZ38),1,0) -> 0 | P38: =IF(AND(P$30>=$AY38,P$30<=$AZ38),1,0) -> 0 | Q38: =IF(AND(Q$30>=$AY38,Q$30<=$AZ38),1,0) -> 0 | ... AW38: =IF(AND(AW$30>=$AY38,AW$30<=$AZ38),1,0) -> 0 | AY38: =DATE(YEAR(AY37),MONTH(AY37)+F32,1) -> 1 | AZ38: =DATE(YEAR(AY38),MONTH(AY38)+F38,1) -> 1
B39: Legalização | J39: =IF(AND(J$30>=$AY39,J$30<=$AZ39),1,0) -> 0 | K39: =IF(AND(K$30>=$AY39,K$30<=$AZ39),1,0) -> 0 | L39: =IF(AND(L$30>=$AY39,L$30<=$AZ39),1,0) -> 0 | M39: =IF(AND(M$30>=$AY39,M$30<=$AZ39),1,0) -> 0 | N39: =IF(AND(N$30>=$AY39,N$30<=$AZ39),1,0) -> 0 | O39: =IF(AND(O$30>=$AY39,O$30<=$AZ39),1,0) -> 0 | P39: =IF(AND(P$30>=$AY39,P$30<=$AZ39),1,0) -> 0 | Q39: =IF(AND(Q$30>=$AY39,Q$30<=$AZ39),1,0) -> 0 | ... AW39: =IF(AND(AW$30>=$AY39,AW$30<=$AZ39),1,0) -> 0 | AY39: =AZ38 -> 1 | AZ39: =DATE(YEAR(AY39),MONTH(AY39)+F39,1) -> 1
B41: QUADRO RESUMO
J43: UNIDADES | R43: ÁREA PRIVATIVA | AH43: VALOR GERAL DE VENDA (VGV)
B44: Vendável | J44: =J46-J45 -> 0 | R44: =R46-R45 -> 0 | AB44: =IFERROR(R44/R46,"") | AH44: =AH46-AH45 -> 0 | AR44: =IFERROR(AH44/AH46,"")
B45: Permuta | J45: =SUM(AR15:AW26) -> 0 | R45: =SUMPRODUCT(K15:K26,AR15:AR26) -> 0 | AB45: =IFERROR(R45/R46,"") | AH45: =SUMPRODUCT(K15:K26,AR15:AR26,Z15:Z26) -> 0 | AR45: =IFERROR(AH45/AH46,"")
B46: TOTAL | J46: =SUM(T15:Y26) -> 0 | R46: =SUMPRODUCT(K15:K26,T15:T26) -> 0 | AH46: =SUMPRODUCT(K15:K26,T15:T26,Z15:Z26) -> 0
B48: ÁREA DO LOTE | Z48: EFICIÊNCIA | AH48: C.A.
B49: ÁREA TOTAL CONSTRUÍDA | Z49: =IFERROR(R46/J49,"") | AH49: =IFERROR(J50/J48,"")
B50: ÁREA COMPUTÁVEL
B52: LOTE
B54: PERMUTA | J54: =AH45 -> 0
B55: PAGAMENTO | Z55: CUSTO BASE
B56: PERMUTA FINANCEIRA | Z56: =SUM(J54:Q57) -> 0
B57: PERMUTA FÍSICA FORA | Z57: =IFERROR(Z56/J48,"")
B58: COMISSÃO | N58: =(SUM(J54:K57))*J58 -> 0
...

Sheet SIMULAÇÃO 04
B6: ANÁLISE DE VIABILIDADE FINANCEIRA PRELIMINAR | AR6: SIMULAÇÃO 04
B8: INFORMAÇÕES DO EMPREENDIMENTO
B10: OBRA | H10: ='SIMULAÇÃO 01'!H10 -> Ed. Curupira | EW Esteves Construções | T10: CIDADE / UF | Z10: ='SIMULAÇÃO 01'!Z10 -> Ribeirão Preto / SP | AI10: PREÇO M² | AO10: ='SIMULAÇÃO 01'!AO10 -> 6682.9332
B12: MAPA DAS UNIDADES
B14: TIPOLOGIA | K14: ÁREA PRIVATIVA | T14: QUANT. | Z14: PREÇO M² | AI14: VALOR / UNIDADE | AR14: PERMUTA
Z15: =IF(B15<>"",$AO$10,"") | AI15: =IF(K15=""," ",IF(Z15=""," ",Z15*K15))
Z16: =IF(B16<>"",$AO$10,"") | AI16: =IF(K16=""," ",IF(Z16=""," ",Z16*K16))
Z17: =IF(B17<>"",$AO$10,"") | AI17: =IF(K17=""," ",IF(Z17=""," ",Z17*K17))
Z18: =IF(B18<>"",$AO$10,"") | AI18: =IF(K18=""," ",IF(Z18=""," ",Z18*K18))
Z19: =IF(B19<>"",$AO$10,"") | AI19: =IF(K19=""," ",IF(Z19=""," ",Z19*K19))
Z20: =IF(B20<>"",$AO$10,"") | AI20: =IF(K20=""," ",IF(Z20=""," ",Z20*K20))
Z21: =IF(B21<>"",$AO$10,"") | AI21: =IF(K21=""," ",IF(Z21=""," ",Z21*K21))
Z22: =IF(B22<>"",$AO$10,"") | AI22: =IF(K22=""," ",IF(Z22=""," ",Z22*K22))
Z23: =IF(B23<>"",$AO$10,"") | AI23: =IF(K23=""," ",IF(Z23=""," ",Z23*K23))
Z24: =IF(B24<>"",$AO$10,"") | AI24: =IF(K24=""," ",IF(Z24=""," ",Z24*K24))
Z25: =IF(B25<>"",$AO$10,"") | AI25: =IF(K25=""," ",IF(Z25=""," ",Z25*K25))
Z26: =IF(B26<>"",$AO$10,"") | AI26: =IF(K26=""," ",IF(Z26=""," ",Z26*K26))
B28: LINHA DO TEMPO | AI28: ESCALA: | AR28: MENSAL
B30: INÍCIO | J30: =IF(F30="","",F30) | K30: =IFERROR(DATE(YEAR(J30),IF($AR$28="MENSAL",MONTH(J30)+1,MONTH(J30)+2),1),"") | L30: =IFERROR(DATE(YEAR(K30),IF($AR$28="MENSAL",MONTH(K30)+1,MONTH(K30)+2),1),"") | M30: =IFERROR(DATE(YEAR(L30),IF($AR$28="MENSAL",MONTH(L30)+1,MONTH(L30)+2),1),"") | N30: =IFERROR(DATE(YEAR(M30),IF($AR$28="MENSAL",MONTH(M30)+1,MONTH(M30)+2),1),"") | O30: =IFERROR(DATE(YEAR(N30),IF($AR$28="MENSAL",MONTH(N30)+1,MONTH(N30)+2),1),"") | P30: =IFERROR(DATE(YEAR(O30),IF($AR$28="MENSAL",MONTH(O30)+1,MONTH(O30)+2),1),"") | Q30: =IFERROR(DATE(YEAR(P30),IF($AR$28="MENSAL",MONTH(P30)+1,MONTH(P30)+2),1),"") | R30: =IFERROR(DATE(YEAR(Q30),IF($AR$28="MENSAL",MONTH(Q30)+1,MONTH(Q30)+2),1),"") | ... AW30: =IFERROR(DATE(YEAR(AV30),IF($AR$28="MENSAL",MONTH(AV30)+1,MONTH(AV30)+2),1),"")
B32: START VENDAS
B34: ETAPA | F34: MESES | AY34: I | AZ34: T
B35: Viabilidade | J35: =IF(AND(J$30>=$AY35,J$30<=$AZ35),1,0) -> 0 | K35: =IF(AND(K$30>=$AY35,K$30<=$AZ35),1,0) -> 0 | L35: =IF(AND(L$30>=$AY35,L$30<=$AZ35),1,0) -> 0 | M35: =IF(AND(M$30>=$AY35,M$30<=$AZ35),1,0) -> 0 | N35: =IF(AND(N$30>=$AY35,N$30<=$AZ35),1,0) -> 0 | O35: =IF(AND(O$30>=$AY35,O$30<=$AZ35),1,0) -> 0 | P35: =IF(AND(P$30>=$AY35,P$30<=$AZ35),1,0) -> 0 | Q35: =IF(AND(Q$30>=$AY35,Q$30<=$AZ35),1,0) -> 0 | ... AW35: =IF(AND(AW$30>=$AY35,AW$30<=$AZ35),1,0) -> 0 | AY35: =F30 -> 0 | AZ35: =DATE(YEAR(AY35),MONTH(AY35)+F35,1) -> 1
B36: Aprovação | J36: =IF(AND(J$30>=$AY36,J$30<=$AZ36),1,0) -> 0 | K36: =IF(AND(K$30>=$AY36,K$30<=$AZ36),1,0) -> 0 | L36: =IF(AND(L$30>=$AY36,L$30<=$AZ36),1,0) -> 0 | M36: =IF(AND(M$30>=$AY36,M$30<=$AZ36),1,0) -> 0 | N36: =IF(AND(N$30>=$AY36,N$30<=$AZ36),1,0) -> 0 | O36: =IF(AND(O$30>=$AY36,O$30<=$AZ36),1,0) -> 0 | P36: =IF(AND(P$30>=$AY36,P$30<=$AZ36),1,0) -> 0 | Q36: =IF(AND(Q$30>=$AY36,Q$30<=$AZ36),1,0) -> 0 | ... AW36: =IF(AND(AW$30>=$AY36,AW$30<=$AZ36),1,0) -> 0 | AY36: =AZ35 -> 1 | AZ36: =DATE(YEAR(AY36),MONTH(AY36)+F36,1) -> 1
B37: Vendas | J37: =IF(AND(J$30>=$AY37,J$30<=$AZ37),1,0) -> 0 | K37: =IF(AND(K$30>=$AY37,K$30<=$AZ37),1,0) -> 0 | L37: =IF(AND(L$30>=$AY37,L$30<=$AZ37),1,0) -> 0 | M37: =IF(AND(M$30>=$AY37,M$30<=$AZ37),1,0) -> 0 | N37: =IF(AND(N$30>=$AY37,N$30<=$AZ37),1,0) -> 0 | O37: =IF(AND(O$30>=$AY37,O$30<=$AZ37),1,0) -> 0 | P37: =IF(AND(P$30>=$AY37,P$30<=$AZ37),1,0) -> 0 | Q37: =IF(AND(Q$30>=$AY37,Q$30<=$AZ37),1,0) -> 0 | ... AW37: =IF(AND(AW$30>=$AY37,AW$30<=$AZ37),1,0) -> 0 | AY37: =AZ36 -> 1 | AZ37: =DATE(YEAR(AY37),MONTH(AY37)+F37,1) -> 1
B38: Obras | J38: =IF(AND(J$30>=$AY38,J$30<=$AZ38),1,0) -> 0 | K38: =IF(AND(K$30>=$AY38,K$30<=$AZ38),1,0) -> 0 | L38: =IF(AND(L$30>=$AY38,L$30<=$AZ38),1,0) -> 0 | M38: =IF(AND(M$30>=$AY38,M$30<=$AZ38),1,0) -> 0 | N38: =IF(AND(N$30>=$AY38,N$30<=$AZ38),1,0) -> 0 | O38: =IF(AND(O$30>=$AY38,O$30<=$AZ38),1,0) -> 0 | P38: =IF(AND(P$30>=$AY38,P$30<=$AZ38),1,0) -> 0 | Q38: =IF(AND(Q$30>=$AY38,Q$30<=$AZ38),1,0) -> 0 | ... AW38: =IF(AND(AW$30>=$AY38,AW$30<=$AZ38),1,0) -> 0 | AY38: =DATE(YEAR(AY37),MONTH(AY37)+F32,1) -> 1 | AZ38: =DATE(YEAR(AY38),MONTH(AY38)+F38,1) -> 1
B39: Legalização | J39: =IF(AND(J$30>=$AY39,J$30<=$AZ39),1,0) -> 0 | K39: =IF(AND(K$30>=$AY39,K$30<=$AZ39),1,0) -> 0 | L39: =IF(AND(L$30>=$AY39,L$30<=$AZ39),1,0) -> 0 | M39: =IF(AND(M$30>=$AY39,M$30<=$AZ39),1,0) -> 0 | N39: =IF(AND(N$30>=$AY39,N$30<=$AZ39),1,0) -> 0 | O39: =IF(AND(O$30>=$AY39,O$30<=$AZ39),1,0) -> 0 | P39: =IF(AND(P$30>=$AY39,P$30<=$AZ39),1,0) -> 0 | Q39: =IF(AND(Q$30>=$AY39,Q$30<=$AZ39),1,0) -> 0 | ... AW39: =IF(AND(AW$30>=$AY39,AW$30<=$AZ39),1,0) -> 0 | AY39: =AZ38 -> 1 | AZ39: =DATE(YEAR(AY39),MONTH(AY39)+F39,1) -> 1
B41: QUADRO RESUMO
J43: UNIDADES | R43: ÁREA PRIVATIVA | AH43: VALOR GERAL DE VENDA (VGV)
B44: Vendável | J44: =J46-J45 -> 0 | R44: =R46-R45 -> 0 | AB44: =IFERROR(R44/R46,"") | AH44: =AH46-AH45 -> 0 | AR44: =IFERROR(AH44/AH46,"")
B45: Permuta | J45: =SUM(AR15:AW26) -> 0 | R45: =SUMPRODUCT(K15:K26,AR15:AR26) -> 0 | AB45: =IFERROR(R45/R46,"") | AH45: =SUMPRODUCT(K15:K26,AR15:AR26,Z15:Z26) -> 0 | AR45: =IFERROR(AH45/AH46,"")
B46: TOTAL | J46: =SUM(T15:Y26) -> 0 | R46: =SUMPRODUCT(K15:K26,T15:T26) -> 0 | AH46: =SUMPRODUCT(K15:K26,T15:T26,Z15:Z26) -> 0
B48: ÁREA DO LOTE | Z48: EFICIÊNCIA | AH48: C.A.
B49: ÁREA TOTAL CONSTRUÍDA | Z49: =IFERROR(R46/J49,"") | AH49: =IFERROR(J50/J48,"")
B50: ÁREA COMPUTÁVEL
B52: LOTE
B54: PERMUTA | J54: =AH45 -> 0
B55: PAGAMENTO | Z55: CUSTO BASE
B56: PERMUTA FINANCEIRA | Z56: =SUM(J54:Q57) -> 0
B57: PERMUTA FÍSICA FORA | Z57: =IFERROR(Z56/J48,"")
B58: COMISSÃO | N58: =(SUM(J54:K57))*J58 -> 0
...

Sheet COMPARATIVO
B6: ANÁLISE COMPARATIVA DE SIMULAÇÕES | AJ6: VALOR: | AQ6: GLOBAL
V8: SIMULAÇÃO 01 | AC8: SIMULAÇÃO 02 | AJ8: SIMULAÇÃO 03 | AQ8: SIMULAÇÃO 04
D10: RECEITA DE VENDAS | V10: {=_xlfn.IFS($AQ$6="GLOBAL",'SIMULAÇÃO 01'!AH181,$AQ$6="POR UNIDADE",'SIMULAÇÃO 01'!AN181)} -> 9556594.4 | AC10: {=_xlfn.IFS($AQ$6="GLOBAL",'SIMULAÇÃO 02'!AO181,$AQ$6="POR UNIDADE",'SIMULAÇÃO 02'!AU181)} -> 0 | AJ10: {=_xlfn.IFS($AQ$6="GLOBAL",'SIMULAÇÃO 03'!AV181,$AQ$6="POR UNIDADE",'SIMULAÇÃO 03'!BB181)} -> 0 | AQ10: {=_xlfn.IFS($AQ$6="GLOBAL",'SIMULAÇÃO 04'!BC181,$AQ$6="POR UNIDADE",'SIMULAÇÃO 04'!BI181)} -> 0
B11: Terreno | D11: Negociação do Lote | V11: {=_xlfn.IFS($AQ$6="GLOBAL",'SIMULAÇÃO 01'!AH182,$AQ$6="POR UNIDADE",'SIMULAÇÃO 01'!AN182)} -> -800000 | AC11: {=_xlfn.IFS($AQ$6="GLOBAL",'SIMULAÇÃO 02'!AO182,$AQ$6="POR UNIDADE",'SIMULAÇÃO 02'!AU182)} -> 0 | AJ11: {=_xlfn.IFS($AQ$6="GLOBAL",'SIMULAÇÃO 03'!AV182,$AQ$6="POR UNIDADE",'SIMULAÇÃO 03'!BB182)} -> 0 | AQ11: {=_xlfn.IFS($AQ$6="GLOBAL",'SIMULAÇÃO 04'!BC182,$AQ$6="POR UNIDADE",'SIMULAÇÃO 04'!BI182)} -> 0
D12: Comissão, ITBI e Registro | V12: {=_xlfn.IFS($AQ$6="GLOBAL",'SIMULAÇÃO 01'!AH183,$AQ$6="POR UNIDADE",'SIMULAÇÃO 01'!AN183)} -> -4000 | AC12: {=_xlfn.IFS($AQ$6="GLOBAL",'SIMULAÇÃO 02'!AO183,$AQ$6="POR UNIDADE",'SIMULAÇÃO 02'!AU183)} -> 0 | AJ12: {=_xlfn.IFS($AQ$6="GLOBAL",'SIMULAÇÃO 03'!AV183,$AQ$6="POR UNIDADE",'SIMULAÇÃO 03'!BB183)} -> 0 | AQ12: {=_xlfn.IFS($AQ$6="GLOBAL",'SIMULAÇÃO 04'!BC183,$AQ$6="POR UNIDADE",'SIMULAÇÃO 04'!BI183)} -> 0
D13: Outorga Onerosa | V13: {=_xlfn.IFS($AQ$6="GLOBAL",'SIMULAÇÃO 01'!AH184,$AQ$6="POR UNIDADE",'SIMULAÇÃO 01'!AN184)} -> 0 | AC13: {=_xlfn.IFS($AQ$6="GLOBAL",'SIMULAÇÃO 02'!AO184,$AQ$6="POR UNIDADE",'SIMULAÇÃO 02'!AU184)} -> 0 | AJ13: {=_xlfn.IFS($AQ$6="GLOBAL",'SIMULAÇÃO 03'!AV184,$AQ$6="POR UNIDADE",'SIMULAÇÃO 03'!BB184)} -> 0 | AQ13: {=_xlfn.IFS($AQ$6="GLOBAL",'SIMULAÇÃO 04'!BC184,$AQ$6="POR UNIDADE",'SIMULAÇÃO 04'!BI184)} -> 0
D14: CEPAC | V14: {=_xlfn.IFS($AQ$6="GLOBAL",'SIMULAÇÃO 01'!AH185,$AQ$6="POR UNIDADE",'SIMULAÇÃO 01'!AN185)} -> 0 | AC14: {=_xlfn.IFS($AQ$6="GLOBAL",'SIMULAÇÃO 02'!AO185,$AQ$6="POR UNIDADE",'SIMULAÇÃO 02'!AU185)} -> 0 | AJ14: {=_xlfn.IFS($AQ$6="GLOBAL",'SIMULAÇÃO 03'!AV185,$AQ$6="POR UNIDADE",'SIMULAÇÃO 03'!BB185)} -> 0 | AQ14: {=_xlfn.IFS($AQ$6="GLOBAL",'SIMULAÇÃO 04'!BC185,$AQ$6="POR UNIDADE",'SIMULAÇÃO 04'!BI185)} -> 0
B15: Obra | D15: Custo Obra | V15: {=_xlfn.IFS($AQ$6="GLOBAL",'SIMULAÇÃO 01'!AH186,$AQ$6="POR UNIDADE",'SIMULAÇÃO 01'!AN186)} -> -4433311.8 | AC15: {=_xlfn.IFS($AQ$6="GLOBAL",'SIMULAÇÃO 02'!AO186,$AQ$6="POR UNIDADE",'SIMULAÇÃO 02'!AU186)} -> 0 | AJ15: {=_xlfn.IFS($AQ$6="GLOBAL",'SIMULAÇÃO 03'!AV186,$AQ$6="POR UNIDADE",'SIMULAÇÃO 03'!BB186)} -> 0 | AQ15: {=_xlfn.IFS($AQ$6="GLOBAL",'SIMULAÇÃO 04'!BC186,$AQ$6="POR UNIDADE",'SIMULAÇÃO 04'!BI186)} -> 0
D16: Taxa de Administração de Obra | V16: {=_xlfn.IFS($AQ$6="GLOBAL",'SIMULAÇÃO 01'!AH187,$AQ$6="POR UNIDADE",'SIMULAÇÃO 01'!AN187)} -> -443331.18 | AC16: {=_xlfn.IFS($AQ$6="GLOBAL",'SIMULAÇÃO 02'!AO187,$AQ$6="POR UNIDADE",'SIMULAÇÃO 02'!AU187)} -> 0 | AJ16: {=_xlfn.IFS($AQ$6="GLOBAL",'SIMULAÇÃO 03'!AV187,$AQ$6="POR UNIDADE",'SIMULAÇÃO 03'!BB187)} -> 0 | AQ16: {=_xlfn.IFS($AQ$6="GLOBAL",'SIMULAÇÃO 04'!BC187,$AQ$6="POR UNIDADE",'SIMULAÇÃO 04'!BI187)} -> 0
B17: Taxas, Custos e Despesas Extras | D17: Projetos | V17: {=_xlfn.IFS($AQ$6="GLOBAL",'SIMULAÇÃO 01'!AH188,$AQ$6="POR UNIDADE",'SIMULAÇÃO 01'!AN188)} -> -62000 | AC17: {=_xlfn.IFS($AQ$6="GLOBAL",'SIMULAÇÃO 02'!AO188,$AQ$6="POR UNIDADE",'SIMULAÇÃO 02'!AU188)} -> 0 | AJ17: {=_xlfn.IFS($AQ$6="GLOBAL",'SIMULAÇÃO 03'!AV188,$AQ$6="POR UNIDADE",'SIMULAÇÃO 03'!BB188)} -> 0 | AQ17: {=_xlfn.IFS($AQ$6="GLOBAL",'SIMULAÇÃO 04'!BC188,$AQ$6="POR UNIDADE",'SIMULAÇÃO 04'!BI188)} -> 0
D18: Despesas Legais | V18: {=_xlfn.IFS($AQ$6="GLOBAL",'SIMULAÇÃO 01'!AH189,$AQ$6="POR UNIDADE",'SIMULAÇÃO 01'!AN189)} -> -8000 | AC18: {=_xlfn.IFS($AQ$6="GLOBAL",'SIMULAÇÃO 02'!AO189,$AQ$6="POR UNIDADE",'SIMULAÇÃO 02'!AU189)} -> 0 | AJ18: {=_xlfn.IFS($AQ$6="GLOBAL",'SIMULAÇÃO 03'!AV189,$AQ$6="POR UNIDADE",'SIMULAÇÃO 03'!BB189)} -> 0 | AQ18: {=_xlfn.IFS($AQ$6="GLOBAL",'SIMULAÇÃO 04'!BC189,$AQ$6="POR UNIDADE",'SIMULAÇÃO 04'!BI189)} -> 0
D19: Aprovação CEF | V19: {=_xlfn.IFS($AQ$6="GLOBAL",'SIMULAÇÃO 01'!AH190,$AQ$6="POR UNIDADE",'SIMULAÇÃO 01'!AN190)} -> 0 | AC19: {=_xlfn.IFS($AQ$6="GLOBAL",'SIMULAÇÃO 02'!AO190,$AQ$6="POR UNIDADE",'SIMULAÇÃO 02'!AU190)} -> 0 | AJ19: {=_xlfn.IFS($AQ$6="GLOBAL",'SIMULAÇÃO 03'!AV190,$AQ$6="POR UNIDADE",'SIMULAÇÃO 03'!BB190)} -> 0 | AQ19: {=_xlfn.IFS($AQ$6="GLOBAL",'SIMULAÇÃO 04'!BC190,$AQ$6="POR UNIDADE",'SIMULAÇÃO 04'!BI190)} -> 0
D20: Demolições | V20: {=_xlfn.IFS($AQ$6="GLOBAL",'SIMULAÇÃO 01'!AH191,$AQ$6="POR UNIDADE",'SIMULAÇÃO 01'!AN191)} -> 0 | AC20: {=_xlfn.IFS($AQ$6="GLOBAL",'SIMULAÇÃO 02'!AO191,$AQ$6="POR UNIDADE",'SIMULAÇÃO 02'!AU191)} -> 0 | AJ20: {=_xlfn.IFS($AQ$6="GLOBAL",'SIMULAÇÃO 03'!AV191,$AQ$6="POR UNIDADE",'SIMULAÇÃO 03'!BB191)} -> 0 | AQ20: {=_xlfn.IFS($AQ$6="GLOBAL",'SIMULAÇÃO 04'!BC191,$AQ$6="POR UNIDADE",'SIMULAÇÃO 04'!BI191)} -> 0
D21: Canteiro | V21: {=_xlfn.IFS($AQ$6="GLOBAL",'SIMULAÇÃO 01'!AH192,$AQ$6="POR UNIDADE",'SIMULAÇÃO 01'!AN192)} -> 0 | AC21: {=_xlfn.IFS($AQ$6="GLOBAL",'SIMULAÇÃO 02'!AO192,$AQ$6="POR UNIDADE",'SIMULAÇÃO 02'!AU192)} -> 0 | AJ21: {=_xlfn.IFS($AQ$6="GLOBAL",'SIMULAÇÃO 03'!AV192,$AQ$6="POR UNIDADE",'SIMULAÇÃO 03'!BB192)} -> 0 | AQ21: {=_xlfn.IFS($AQ$6="GLOBAL",'SIMULAÇÃO 04'!BC192,$AQ$6="POR UNIDADE",'SIMULAÇÃO 04'!BI192)} -> 0
D22: Máquinas e Equipamentos | V22: {=_xlfn.IFS($AQ$6="GLOBAL",'SIMULAÇÃO 01'!AH193,$AQ$6="POR UNIDADE",'SIMULAÇÃO 01'!AN193)} -> 0 | AC22: {=_xlfn.IFS($AQ$6="GLOBAL",'SIMULAÇÃO 02'!AO193,$AQ$6="POR UNIDADE",'SIMULAÇÃO 02'!AU193)} -> 0 | AJ22: {=_xlfn.IFS($AQ$6="GLOBAL",'SIMULAÇÃO 03'!AV193,$AQ$6="POR UNIDADE",'SIMULAÇÃO 03'!BB193)} -> 0 | AQ22: {=_xlfn.IFS($AQ$6="GLOBAL",'SIMULAÇÃO 04'!BC193,$AQ$6="POR UNIDADE",'SIMULAÇÃO 04'!BI193)} -> 0
D23: Regularização | V23: {=_xlfn.IFS($AQ$6="GLOBAL",'SIMULAÇÃO 01'!AH194,$AQ$6="POR UNIDADE",'SIMULAÇÃO 01'!AN194)} -> -286697.83 | AC23: {=_xlfn.IFS($AQ$6="GLOBAL",'SIMULAÇÃO 02'!AO194,$AQ$6="POR UNIDADE",'SIMULAÇÃO 02'!AU194)} -> 0 | AJ23: {=_xlfn.IFS($AQ$6="GLOBAL",'SIMULAÇÃO 03'!AV194,$AQ$6="POR UNIDADE",'SIMULAÇÃO 03'!BB194)} -> 0 | AQ23: {=_xlfn.IFS($AQ$6="GLOBAL",'SIMULAÇÃO 04'!BC194,$AQ$6="POR UNIDADE",'SIMULAÇÃO 04'!BI194)} -> 0
D24: Infraestrutura não Incidente | V24: {=_xlfn.IFS($AQ$6="GLOBAL",'SIMULAÇÃO 01'!AH195,$AQ$6="POR UNIDADE",'SIMULAÇÃO 01'!AN195)} -> 0 | AC24: {=_xlfn.IFS($AQ$6="GLOBAL",'SIMULAÇÃO 02'!AO195,$AQ$6="POR UNIDADE",'SIMULAÇÃO 02'!AU195)} -> 0 | AJ24: {=_xlfn.IFS($AQ$6="GLOBAL",'SIMULAÇÃO 03'!AV195,$AQ$6="POR UNIDADE",'SIMULAÇÃO 03'!BB195)} -> 0 | AQ24: {=_xlfn.IFS($AQ$6="GLOBAL",'SIMULAÇÃO 04'!BC195,$AQ$6="POR UNIDADE",'SIMULAÇÃO 04'!BI195)} -> 0
D25: Assistência Técnica | V25: {=_xlfn.IFS($AQ$6="GLOBAL",'SIMULAÇÃO 01'!AH196,$AQ$6="POR UNIDADE",'SIMULAÇÃO 01'!AN196)} -> -44333.118 | AC25: {=_xlfn.IFS($AQ$6="GLOBAL",'SIMULAÇÃO 02'!AO196,$AQ$6="POR UNIDADE",'SIMULAÇÃO 02'!AU196)} -> 0 | AJ25: {=_xlfn.IFS($AQ$6="GLOBAL",'SIMULAÇÃO 03'!AV196,$AQ$6="POR UNIDADE",'SIMULAÇÃO 03'!BB196)} -> 0 | AQ25: {=_xlfn.IFS($AQ$6="GLOBAL",'SIMULAÇÃO 04'!BC196,$AQ$6="POR UNIDADE",'SIMULAÇÃO 04'!BI196)} -> 0
D26: Gestão do Projeto | V26: {=_xlfn.IFS($AQ$6="GLOBAL",'SIMULAÇÃO 01'!AH197,$AQ$6="POR UNIDADE",'SIMULAÇÃO 01'!AN197)} -> 0 | AC26: {=_xlfn.IFS($AQ$6="GLOBAL",'SIMULAÇÃO 02'!AO197,$AQ$6="POR UNIDADE",'SIMULAÇÃO 02'!AU197)} -> 0 | AJ26: {=_xlfn.IFS($AQ$6="GLOBAL",'SIMULAÇÃO 03'!AV197,$AQ$6="POR UNIDADE",'SIMULAÇÃO 03'!BB197)} -> 0 | AQ26: {=_xlfn.IFS($AQ$6="GLOBAL",'SIMULAÇÃO 04'!BC197,$AQ$6="POR UNIDADE",'SIMULAÇÃO 04'!BI197)} -> 0
D27: IPTU | V27: {=_xlfn.IFS($AQ$6="GLOBAL",'SIMULAÇÃO 01'!AH198,$AQ$6="POR UNIDADE",'SIMULAÇÃO 01'!AN198)} -> 0 | AC27: {=_xlfn.IFS($AQ$6="GLOBAL",'SIMULAÇÃO 02'!AO198,$AQ$6="POR UNIDADE",'SIMULAÇÃO 02'!AU198)} -> 0 | AJ27: {=_xlfn.IFS($AQ$6="GLOBAL",'SIMULAÇÃO 03'!AV198,$AQ$6="POR UNIDADE",'SIMULAÇÃO 03'!BB198)} -> 0 | AQ27: {=_xlfn.IFS($AQ$6="GLOBAL",'SIMULAÇÃO 04'!BC198,$AQ$6="POR UNIDADE",'SIMULAÇÃO 04'!BI198)} -> 0
D28: Outros | V28: {=_xlfn.IFS($AQ$6="GLOBAL",'SIMULAÇÃO 01'!AH199,$AQ$6="POR UNIDADE",'SIMULAÇÃO 01'!AN199)} -> -260000 | AC28: {=_xlfn.IFS($AQ$6="GLOBAL",'SIMULAÇÃO 02'!AO199,$AQ$6="POR UNIDADE",'SIMULAÇÃO 02'!AU199)} -> 0 | AJ28: {=_xlfn.IFS($AQ$6="GLOBAL",'SIMULAÇÃO 03'!AV199,$AQ$6="POR UNIDADE",'SIMULAÇÃO 03'!BB199)} -> 0 | AQ28: {=_xlfn.IFS($AQ$6="GLOBAL",'SIMULAÇÃO 04'!BC199,$AQ$6="POR UNIDADE",'SIMULAÇÃO 04'!BI199)} -> 0
D29: Incorporação | V29: {=_xlfn.IFS($AQ$6="GLOBAL",'SIMULAÇÃO 01'!AH200,$AQ$6="POR UNIDADE",'SIMULAÇÃO 01'!AN200)} -> -34796.45 | AC29: {=_xlfn.IFS($AQ$6="GLOBAL",'SIMULAÇÃO 02'!AO200,$AQ$6="POR UNIDADE",'SIMULAÇÃO 02'!AU200)} -> 0 | AJ29: {=_xlfn.IFS($AQ$6="GLOBAL",'SIMULAÇÃO 03'!AV200,$AQ$6="POR UNIDADE",'SIMULAÇÃO 03'!BB200)} -> 0 | AQ29: {=_xlfn.IFS($AQ$6="GLOBAL",'SIMULAÇÃO 04'!BC200,$AQ$6="POR UNIDADE",'SIMULAÇÃO 04'!BI200)} -> 0
B30: Comercialização | D30: Corretagem | V30: {=_xlfn.IFS($AQ$6="GLOBAL",'SIMULAÇÃO 01'!AH201,$AQ$6="POR UNIDADE",'SIMULAÇÃO 01'!AN201)} -> -477829.72 | AC30: {=_xlfn.IFS($AQ$6="GLOBAL",'SIMULAÇÃO 02'!AO201,$AQ$6="POR UNIDADE",'SIMULAÇÃO 02'!AU201)} -> 0 | AJ30: {=_xlfn.IFS($AQ$6="GLOBAL",'SIMULAÇÃO 03'!AV201,$AQ$6="POR UNIDADE",'SIMULAÇÃO 03'!BB201)} -> 0 | AQ30: {=_xlfn.IFS($AQ$6="GLOBAL",'SIMULAÇÃO 04'!BC201,$AQ$6="POR UNIDADE",'SIMULAÇÃO 04'!BI201)} -> 0
D31: Administração de Vendas | V31: {=_xlfn.IFS($AQ$6="GLOBAL",'SIMULAÇÃO 01'!AH202,$AQ$6="POR UNIDADE",'SIMULAÇÃO 01'!AN202)} -> -95565.944 | AC31: {=_xlfn.IFS($AQ$6="GLOBAL",'SIMULAÇÃO 02'!AO202,$AQ$6="POR UNIDADE",'SIMULAÇÃO 02'!AU202)} -> 0 | AJ31: {=_xlfn.IFS($AQ$6="GLOBAL",'SIMULAÇÃO 03'!AV202,$AQ$6="POR UNIDADE",'SIMULAÇÃO 03'!BB202)} -> 0 | AQ31: {=_xlfn.IFS($AQ$6="GLOBAL",'SIMULAÇÃO 04'!BC202,$AQ$6="POR UNIDADE",'SIMULAÇÃO 04'!BI202)} -> 0
D32: Marketing e Publicidade | V32: {=_xlfn.IFS($AQ$6="GLOBAL",'SIMULAÇÃO 01'!AH203,$AQ$6="POR UNIDADE",'SIMULAÇÃO 01'!AN203)} -> -47782.972 | AC32: {=_xlfn.IFS($AQ$6="GLOBAL",'SIMULAÇÃO 02'!AO203,$AQ$6="POR UNIDADE",'SIMULAÇÃO 02'!AU203)} -> 0 | AJ32: {=_xlfn.IFS($AQ$6="GLOBAL",'SIMULAÇÃO 03'!AV203,$AQ$6="POR UNIDADE",'SIMULAÇÃO 03'!BB203)} -> 0 | AQ32: {=_xlfn.IFS($AQ$6="GLOBAL",'SIMULAÇÃO 04'!BC203,$AQ$6="POR UNIDADE",'SIMULAÇÃO 04'!BI203)} -> 0
D33: Stand de Vendas | V33: {=_xlfn.IFS($AQ$6="GLOBAL",'SIMULAÇÃO 01'!AH204,$AQ$6="POR UNIDADE",'SIMULAÇÃO 01'!AN204)} -> 0 | AC33: {=_xlfn.IFS($AQ$6="GLOBAL",'SIMULAÇÃO 02'!AO204,$AQ$6="POR UNIDADE",'SIMULAÇÃO 02'!AU204)} -> 0 | AJ33: {=_xlfn.IFS($AQ$6="GLOBAL",'SIMULAÇÃO 03'!AV204,$AQ$6="POR UNIDADE",'SIMULAÇÃO 03'!BB204)} -> 0 | AQ33: {=_xlfn.IFS($AQ$6="GLOBAL",'SIMULAÇÃO 04'!BC204,$AQ$6="POR UNIDADE",'SIMULAÇÃO 04'!BI204)} -> 0
D34: Apartamento Decorado | V34: {=_xlfn.IFS($AQ$6="GLOBAL",'SIMULAÇÃO 01'!AH205,$AQ$6="POR UNIDADE",'SIMULAÇÃO 01'!AN205)} -> 0 | AC34: {=_xlfn.IFS($AQ$6="GLOBAL",'SIMULAÇÃO 02'!AO205,$AQ$6="POR UNIDADE",'SIMULAÇÃO 02'!AU205)} -> 0 | AJ34: {=_xlfn.IFS($AQ$6="GLOBAL",'SIMULAÇÃO 03'!AV205,$AQ$6="POR UNIDADE",'SIMULAÇÃO 03'!BB205)} -> 0 | AQ34: {=_xlfn.IFS($AQ$6="GLOBAL",'SIMULAÇÃO 04'!BC205,$AQ$6="POR UNIDADE",'SIMULAÇÃO 04'!BI205)} -> 0
D35: Recebimento em Imóveis | V35: {=_xlfn.IFS($AQ$6="GLOBAL",'SIMULAÇÃO 01'!AH206,$AQ$6="POR UNIDADE",'SIMULAÇÃO 01'!AN206)} -> 0 | AC35: {=_xlfn.IFS($AQ$6="GLOBAL",'SIMULAÇÃO 02'!AO206,$AQ$6="POR UNIDADE",'SIMULAÇÃO 02'!AU206)} -> 0 | AJ35: {=_xlfn.IFS($AQ$6="GLOBAL",'SIMULAÇÃO 03'!AV206,$AQ$6="POR UNIDADE",'SIMULAÇÃO 03'!BB206)} -> 0 | AQ35: {=_xlfn.IFS($AQ$6="GLOBAL",'SIMULAÇÃO 04'!BC206,$AQ$6="POR UNIDADE",'SIMULAÇÃO 04'!BI206)} -> 0
D36: Outros | V36: {=_xlfn.IFS($AQ$6="GLOBAL",'SIMULAÇÃO 01'!AH207,$AQ$6="POR UNIDADE",'SIMULAÇÃO 01'!AN207)} -> 0 | AC36: {=_xlfn.IFS($AQ$6="GLOBAL",'SIMULAÇÃO 02'!AO207,$AQ$6="POR UNIDADE",'SIMULAÇÃO 02'!AU207)} -> 0 | AJ36: {=_xlfn.IFS($AQ$6="GLOBAL",'SIMULAÇÃO 03'!AV207,$AQ$6="POR UNIDADE",'SIMULAÇÃO 03'!BB207)} -> 0 | AQ36: {=_xlfn.IFS($AQ$6="GLOBAL",'SIMULAÇÃO 04'!BC207,$AQ$6="POR UNIDADE",'SIMULAÇÃO 04'!BI207)} -> 0
B37: Seguros | D37: Risco de Engenhairia | V37: {=_xlfn.IFS($AQ$6="GLOBAL",'SIMULAÇÃO 01'!AH208,$AQ$6="POR UNIDADE",'SIMULAÇÃO 01'!AN208)} -> -3546.6495 | AC37: {=_xlfn.IFS($AQ$6="GLOBAL",'SIMULAÇÃO 02'!AO208,$AQ$6="POR UNIDADE",'SIMULAÇÃO 02'!AU208)} -> 0 | AJ37: {=_xlfn.IFS($AQ$6="GLOBAL",'SIMULAÇÃO 03'!AV208,$AQ$6="POR UNIDADE",'SIMULAÇÃO 03'!BB208)} -> 0 | AQ37: {=_xlfn.IFS($AQ$6="GLOBAL",'SIMULAÇÃO 04'!BC208,$AQ$6="POR UNIDADE",'SIMULAÇÃO 04'!BI208)} -> 0
D38: Assistência Técnica | V38: {=_xlfn.IFS($AQ$6="GLOBAL",'SIMULAÇÃO 01'!AH209,$AQ$6="POR UNIDADE",'SIMULAÇÃO 01'!AN209)} -> -3546.6495 | AC38: {=_xlfn.IFS($AQ$6="GLOBAL",'SIMULAÇÃO 02'!AO209,$AQ$6="POR UNIDADE",'SIMULAÇÃO 02'!AU209)} -> 0 | AJ38: {=_xlfn.IFS($AQ$6="GLOBAL",'SIMULAÇÃO 03'!AV209,$AQ$6="POR UNIDADE",'SIMULAÇÃO 03'!BB209)} -> 0 | AQ38: {=_xlfn.IFS($AQ$6="GLOBAL",'SIMULAÇÃO 04'!BC209,$AQ$6="POR UNIDADE",'SIMULAÇÃO 04'!BI209)} -> 0
D39: Conclusão de Obra | V39: {=_xlfn.IFS($AQ$6="GLOBAL",'SIMULAÇÃO 01'!AH210,$AQ$6="POR UNIDADE",'SIMULAÇÃO 01'!AN210)} -> -3546.6495 | AC39: {=_xlfn.IFS($AQ$6="GLOBAL",'SIMULAÇÃO 02'!AO210,$AQ$6="POR UNIDADE",'SIMULAÇÃO 02'!AU210)} -> 0 | AJ39: {=_xlfn.IFS($AQ$6="GLOBAL",'SIMULAÇÃO 03'!AV210,$AQ$6="POR UNIDADE",'SIMULAÇÃO 03'!BB210)} -> 0 | AQ39: {=_xlfn.IFS($AQ$6="GLOBAL",'SIMULAÇÃO 04'!BC210,$AQ$6="POR UNIDADE",'SIMULAÇÃO 04'!BI210)} -> 0
D40: Outros | V40: {=_xlfn.IFS($AQ$6="GLOBAL",'SIMULAÇÃO 01'!AH211,$AQ$6="POR UNIDADE",'SIMULAÇÃO 01'!AN211)} -> 0 | AC40: {=_xlfn.IFS($AQ$6="GLOBAL",'SIMULAÇÃO 02'!AO211,$AQ$6="POR UNIDADE",'SIMULAÇÃO 02'!AU211)} -> 0 | AJ40: {=_xlfn.IFS($AQ$6="GLOBAL",'SIMULAÇÃO 03'!AV211,$AQ$6="POR UNIDADE",'SIMULAÇÃO 03'!BB211)} -> 0 | AQ40: {=_xlfn.IFS($AQ$6="GLOBAL",'SIMULAÇÃO 04'!BC211,$AQ$6="POR UNIDADE",'SIMULAÇÃO 04'!BI211)} -> 0
D41: Impostos | V41: {=_xlfn.IFS($AQ$6="GLOBAL",'SIMULAÇÃO 01'!AH212,$AQ$6="POR UNIDADE",'SIMULAÇÃO 01'!AN212)} -> -359327.95 | AC41: {=_xlfn.IFS($AQ$6="GLOBAL",'SIMULAÇÃO 02'!AO212,$AQ$6="POR UNIDADE",'SIMULAÇÃO 02'!AU212)} -> 0 | AJ41: {=_xlfn.IFS($AQ$6="GLOBAL",'SIMULAÇÃO 03'!AV212,$AQ$6="POR UNIDADE",'SIMULAÇÃO 03'!BB212)} -> 0 | AQ41: {=_xlfn.IFS($AQ$6="GLOBAL",'SIMULAÇÃO 04'!BC212,$AQ$6="POR UNIDADE",'SIMULAÇÃO 04'!BI212)} -> 0
D42: Custo de Capital | V42: {=_xlfn.IFS($AQ$6="GLOBAL",'SIMULAÇÃO 01'!AH213,$AQ$6="POR UNIDADE",'SIMULAÇÃO 01'!AN213)} -> -466979.47 | AC42: {=_xlfn.IFS($AQ$6="GLOBAL",'SIMULAÇÃO 02'!AO213,$AQ$6="POR UNIDADE",'SIMULAÇÃO 02'!AU213)} -> 0 | AJ42: {=_xlfn.IFS($AQ$6="GLOBAL",'SIMULAÇÃO 03'!AV213,$AQ$6="POR UNIDADE",'SIMULAÇÃO 03'!BB213)} -> 0 | AQ42: {=_xlfn.IFS($AQ$6="GLOBAL",'SIMULAÇÃO 04'!BC213,$AQ$6="POR UNIDADE",'SIMULAÇÃO 04'!BI213)} -> 0
D43: RESULTADO | V43: {=_xlfn.IFS($AQ$6="GLOBAL",'SIMULAÇÃO 01'!AH214,$AQ$6="POR UNIDADE",'SIMULAÇÃO 01'!AN214)} -> 1721998 | AC43: {=_xlfn.IFS($AQ$6="GLOBAL",'SIMULAÇÃO 02'!AO214,$AQ$6="POR UNIDADE",'SIMULAÇÃO 02'!AU214)} -> 0 | AJ43: {=_xlfn.IFS($AQ$6="GLOBAL",'SIMULAÇÃO 03'!AV214,$AQ$6="POR UNIDADE",'SIMULAÇÃO 03'!BB214)} -> 0 | AQ43: {=_xlfn.IFS($AQ$6="GLOBAL",'SIMULAÇÃO 04'!BC214,$AQ$6="POR UNIDADE",'SIMULAÇÃO 04'!BI214)} -> 0
V44: =IFERROR(V43/V10,0) -> 0.1801895 | AC44: =IFERROR(AC43/AC10,0) -> 0 | AJ44: =IFERROR(AJ43/AJ10,0) -> 0 | AQ44: =IFERROR(AQ43/AQ10,0) -> 0
B46: ANÁLISE GRÁFICA | AQ46: SIMULAÇÃO 01
C49: =AQ46 -> SIMULAÇÃO 01 | E49: SIMULAÇÃO 01 | F49: SIMULAÇÃO 02 | G49: SIMULAÇÃO 03 | H49: SIMULAÇÃO 04
B50: Receita de Vendas | C50: {=_xlfn.IFS($AQ$46="SIMULAÇÃO 01",E50,$AQ$46="SIMULAÇÃO 02",F50,$AQ$46="SIMULAÇÃO 03",G50,$AQ$46="SIMULAÇÃO 04",H50)} -> 9556594.4 | E50: =V10 -> 9556594.4 | F50: =AC10 -> 0 | G50: =AJ10 -> 0 | H50: =AQ10 -> 0
...

Sheet RELATÓRIO
C3: RELATÓRIO DE EQUALIZAÇÃO DE ORÇAMENTO PARA PLANILHA PCI | P3: RELATÓRIO DE EQUALIZAÇÃO DE ORÇAMENTO PARA PLANILHA PCI | AI3: RELATÓRIO DE EQUALIZAÇÃO DE ORÇAMENTO PARA PLANILHA PCI | BB3: RELATÓRIO DE EQUALIZAÇÃO DE ORÇAMENTO PARA PLANILHA PCI
B7: OBRA | C7: ='SIMULAÇÃO 01'!$S$10 -> 0 | F7: DATA | G7: ='SIMULAÇÃO 01'!#REF! -> #REF! | I7: LOCAL | J7: ='SIMULAÇÃO 01'!$Z$10 -> Ribeirão Preto / SP | N7: OBRA | O7: ='SIMULAÇÃO 01'!$S$10 -> 0 | S7: DATA | U7: ='SIMULAÇÃO 01'!#REF! -> #REF! | Y7: LOCAL | AA7: ='SIMULAÇÃO 01'!$Z$10 -> Ribeirão Preto / SP | AG7: OBRA | AH7: ='SIMULAÇÃO 01'!$S$10 -> 0 | AL7: DATA | AN7: ='SIMULAÇÃO 01'!#REF! -> #REF! | AR7: LOCAL | AT7: ='SIMULAÇÃO 01'!$Z$10 -> Ribeirão Preto / SP
B9: ITEM | C9: ETAPA | D9: ORÇAMENTO | F9: EQUALIZAÇÃO | G9: DIFERENÇA | I9: PCI ADOTADO (C/ BDI) | K9: % | N9: ITEM | O9: ETAPA | P9: TOTAL | Q9: PESO | S9: =#REF! -> #REF! | T9: =#REF! -> #REF! | U9: =#REF! -> #REF! | V9: =#REF! -> #REF! | W9: =#REF! -> #REF! | X9: =#REF! -> #REF! | Y9: =#REF! -> #REF! | Z9: =#REF! -> #REF! | ... AD9: =#REF! -> #REF! | AG9: ITEM | AH9: ETAPA | AI9: TOTAL | AJ9: PESO | AL9: =#REF! -> #REF! | AM9: =#REF! -> #REF! | AN9: =#REF! -> #REF! | AO9: =#REF! -> #REF! | AP9: =#REF! -> #REF! | AQ9: =#REF! -> #REF! | AR9: =#REF! -> #REF! | AS9: =#REF! -> #REF! | ... AW9: =#REF! -> #REF!
B11: 1 | C11: =VLOOKUP(B11,#REF!,2,0) -> #REF! | D11: =VLOOKUP(B11,#REF!,10,0) -> #REF! | F11: =VLOOKUP(B11,#REF!,15,0) -> #REF! | G11: =D11-F11 -> #REF! | I11: =VLOOKUP(B11,#REF!,11,0) -> #REF! | K11: =I11/SUM($I$11:$J$50) -> #REF! | N11: 1 | O11: =C11 -> #REF! | P11: =I11 -> #REF! | Q11: =K11 -> #REF! | S11: =#REF! -> #REF! | T11: =#REF! -> #REF! | U11: =#REF! -> #REF! | V11: =#REF! -> #REF! | W11: =#REF! -> #REF! | X11: =#REF! -> #REF! | Y11: =#REF! -> #REF! | Z11: =#REF! -> #REF! | ... AD11: =#REF! -> #REF! | AG11: 1 | AH11: =O11 -> #REF! | AI11: =P11 -> #REF! | AJ11: =Q11 -> #REF! | AL11: =#REF! -> #REF! | AM11: =#REF! -> #REF! | AN11: =#REF! -> #REF! | AO11: =#REF! -> #REF! | AP11: =#REF! -> #REF! | AQ11: =#REF! -> #REF! | AR11: =#REF! -> #REF! | AS11: =#REF! -> #REF! | ... AW11: =#REF! -> #REF!
S12: =#REF! -> #REF! | T12: =#REF! -> #REF! | U12: =#REF! -> #REF! | V12: =#REF! -> #REF! | W12: =#REF! -> #REF! | X12: =#REF! -> #REF! | Y12: =#REF! -> #REF! | Z12: =#REF! -> #REF! | ... AD12: =#REF! -> #REF! | AL12: =#REF! -> #REF! | AM12: =#REF! -> #REF! | AN12: =#REF! -> #REF! | AO12: =#REF! -> #REF! | AP12: =#REF! -> #REF! | AQ12: =#REF! -> #REF! | AR12: =#REF! -> #REF! | AS12: =#REF! -> #REF! | ... AW12: =#REF! -> #REF!
B13: 2 | C13: =VLOOKUP(B13,#REF!,2,0) -> #REF! | D13: =VLOOKUP(B13,#REF!,10,0) -> #REF! | F13: =VLOOKUP(B13,#REF!,15,0) -> #REF! | G13: =D13-F13 -> #REF! | I13: =VLOOKUP(B13,#REF!,11,0) -> #REF! | K13: =I13/SUM($I$11:$J$50) -> #REF! | N13: 2 | O13: =C13 -> #REF! | P13: =I13 -> #REF! | Q13: =K13 -> #REF! | S13: =#REF! -> #REF! | T13: =#REF! -> #REF! | U13: =#REF! -> #REF! | V13: =#REF! -> #REF! | W13: =#REF! -> #REF! | X13: =#REF! -> #REF! | Y13: =#REF! -> #REF! | Z13: =#REF! -> #REF! | ... AD13: =#REF! -> #REF! | AG13: 2 | AH13: =O13 -> #REF! | AI13: =P13 -> #REF! | AJ13: =Q13 -> #REF! | AL13: =#REF! -> #REF! | AM13: =#REF! -> #REF! | AN13: =#REF! -> #REF! | AO13: =#REF! -> #REF! | AP13: =#REF! -> #REF! | AQ13: =#REF! -> #REF! | AR13: =#REF! -> #REF! | AS13: =#REF! -> #REF! | ... AW13: =#REF! -> #REF!
S14: =#REF! -> #REF! | T14: =#REF! -> #REF! | U14: =#REF! -> #REF! | V14: =#REF! -> #REF! | W14: =#REF! -> #REF! | X14: =#REF! -> #REF! | Y14: =#REF! -> #REF! | Z14: =#REF! -> #REF! | ... AD14: =#REF! -> #REF! | AL14: =#REF! -> #REF! | AM14: =#REF! -> #REF! | AN14: =#REF! -> #REF! | AO14: =#REF! -> #REF! | AP14: =#REF! -> #REF! | AQ14: =#REF! -> #REF! | AR14: =#REF! -> #REF! | AS14: =#REF! -> #REF! | ... AW14: =#REF! -> #REF!
B15: 3 | C15: =VLOOKUP(B15,#REF!,2,0) -> #REF! | D15: =VLOOKUP(B15,#REF!,10,0) -> #REF! | F15: =VLOOKUP(B15,#REF!,15,0) -> #REF! | G15: =D15-F15 -> #REF! | I15: =VLOOKUP(B15,#REF!,11,0) -> #REF! | K15: =I15/SUM($I$11:$J$50) -> #REF! | N15: 3 | O15: =C15 -> #REF! | P15: =I15 -> #REF! | Q15: =K15 -> #REF! | S15: =#REF! -> #REF! | T15: =#REF! -> #REF! | U15: =#REF! -> #REF! | V15: =#REF! -> #REF! | W15: =#REF! -> #REF! | X15: =#REF! -> #REF! | Y15: =#REF! -> #REF! | Z15: =#REF! -> #REF! | ... AD15: =#REF! -> #REF! | AG15: 3 | AH15: =O15 -> #REF! | AI15: =P15 -> #REF! | AJ15: =Q15 -> #REF! | AL15: =#REF! -> #REF! | AM15: =#REF! -> #REF! | AN15: =#REF! -> #REF! | AO15: =#REF! -> #REF! | AP15: =#REF! -> #REF! | AQ15: =#REF! -> #REF! | AR15: =#REF! -> #REF! | AS15: =#REF! -> #REF! | ... AW15: =#REF! -> #REF!
S16: =#REF! -> #REF! | T16: =#REF! -> #REF! | U16: =#REF! -> #REF! | V16: =#REF! -> #REF! | W16: =#REF! -> #REF! | X16: =#REF! -> #REF! | Y16: =#REF! -> #REF! | Z16: =#REF! -> #REF! | ... AD16: =#REF! -> #REF! | AL16: =#REF! -> #REF! | AM16: =#REF! -> #REF! | AN16: =#REF! -> #REF! | AO16: =#REF! -> #REF! | AP16: =#REF! -> #REF! | AQ16: =#REF! -> #REF! | AR16: =#REF! -> #REF! | AS16: =#REF! -> #REF! | ... AW16: =#REF! -> #REF!
B17: 4 | C17: =VLOOKUP(B17,#REF!,2,0) -> #REF! | D17: =VLOOKUP(B17,#REF!,10,0) -> #REF! | F17: =VLOOKUP(B17,#REF!,15,0) -> #REF! | G17: =D17-F17 -> #REF! | I17: =VLOOKUP(B17,#REF!,11,0) -> #REF! | K17: =I17/SUM($I$11:$J$50) -> #REF! | N17: 4 | O17: =C17 -> #REF! | P17: =I17 -> #REF! | Q17: =K17 -> #REF! | S17: =#REF! -> #REF! | T17: =#REF! -> #REF! | U17: =#REF! -> #REF! | V17: =#REF! -> #REF! | W17: =#REF! -> #REF! | X17: =#REF! -> #REF! | Y17: =#REF! -> #REF! | Z17: =#REF! -> #REF! | ... AD17: =#REF! -> #REF! | AG17: 4 | AH17: =O17 -> #REF! | AI17: =P17 -> #REF! | AJ17: =Q17 -> #REF! | AL17: =#REF! -> #REF! | AM17: =#REF! -> #REF! | AN17: =#REF! -> #REF! | AO17: =#REF! -> #REF! | AP17: =#REF! -> #REF! | AQ17: =#REF! -> #REF! | AR17: =#REF! -> #REF! | AS17: =#REF! -> #REF! | ... AW17: =#REF! -> #REF!
S18: =#REF! -> #REF! | T18: =#REF! -> #REF! | U18: =#REF! -> #REF! | V18: =#REF! -> #REF! | W18: =#REF! -> #REF! | X18: =#REF! -> #REF! | Y18: =#REF! -> #REF! | Z18: =#REF! -> #REF! | ... AD18: =#REF! -> #REF! | AL18: =#REF! -> #REF! | AM18: =#REF! -> #REF! | AN18: =#REF! -> #REF! | AO18: =#REF! -> #REF! | AP18: =#REF! -> #REF! | AQ18: =#REF! -> #REF! | AR18: =#REF! -> #REF! | AS18: =#REF! -> #REF! | ... AW18: =#REF! -> #REF!
